Workbook

Sheet Lisez-moi
B2: Publications intermédiaires - CGF Gestion
B3: Fichier de suivi à charger dans l'application « Fiche de valeur BRVM », au même titre que le classeur des états financiers et la base de données SMF.
B5: Objet | C5: Suivre, titre par titre, les indicateurs publiés en cours d'exercice : T1 (1er trimestre), S1 (1er semestre) et T3 (3e trimestre). L'application en tire la dynamique de l'exercice en cours : croissance cumulée face à la même période de l'an dernier, tendance d'une publication à l'autre, 12 mois glissants. Cette dynamique s'ajoute aux états financiers complets du dernier exercice clos.
B6: Comment renseigner | C6: 1. Choisissez la feuille « Entreprises » ou « Banques » selon le type du titre (feuille « Titres »). 2. Trouvez la ligne du titre, de l'exercice et de la période, ou ajoutez une ligne sous les dernières. 3. Saisissez les montants de la publication en millions de FCFA, cumulés depuis le 1er janvier. 4. Une publication donne N et N-1 : renseignez aussi la ligne de l'exercice précédent (même période). Les colonnes « Var. ... vs même période N-1 » (à droite, calculées) comparent chaque ligne à la même période de l'exercice précédent. 5. Indiquez le statut, la date de publication et la source (lien richbourse ou brvm.org). 6. Contrôlez la colonne « Contrôle de cohérence » et suivez l'avancement dans « Suivi ».
B7: Cumul et périodes | C7: Toutes les valeurs sont cumulées depuis le 1er janvier : T1 = 3 mois, S1 = 6 mois, T3 = 9 mois. Si une société publie un trimestre isolé, additionnez les trimestres. Les encours bancaires (crédits, dépôts) sont ceux de la fin de période.
B8: Unité et signes | C8: Millions de FCFA. Les charges se saisissent en négatif (frais de gestion, coût du risque). Les autres soldes sont repris tels que publiés. Si le document est en milliers ou en milliards, convertissez en millions.
B9: Retraitements | C9: Si le comparatif N-1 d'une publication diffère du chiffre publié l'an dernier (retraitement), retenez le chiffre de la publication la plus récente et indiquez-le dans la source.
B10: Statuts | C10: Publié : chiffres figurant dans le document publié. Provisoire : communiqué ou chiffres non encore certifiés. À vérifier : valeur à contrôler.
B11: Règles de priorité | C11: Le fichier prime sur la lecture automatique de richbourse.com, qui comble seulement les périodes ou indicateurs absents. Un document PDF chargé dans l'application prime sur la lecture automatique.
B12: 12 mois glissants | C12: 12 mois glissants = exercice N-1 + cumul N - cumul N-1 de la même période. Ils neutralisent la saisonnalité et alimentent le PER glissant, la croissance et la tendance. Ils exigent le dernier exercice clos dans les états financiers ou la base SMF.
B13: Où trouver les chiffres | C13: brvm.org (avis et communiqués), richbourse.com (rubrique Etats financiers : rapports d'activités T1, S1, T3), sites des sociétés.
B14: Code couleur | C14: Texte bleu : saisie. Texte noir : formule, ne pas modifier. Fond gris : colonne calculée.
B16: Société de gestion collective au capital de 500 000 000 FCFA - N° agrément CREPMF SG-003/2001

Sheet Entreprises
A1: Publications intermédiaires (T1, S1, T3) - entreprises
A2: Une ligne par titre, exercice et période. Montants cumulés depuis le 1er janvier (T1 = 3 mois, S1 = 6 mois, T3 = 9 mois), en millions de FCFA, tels que publiés. Charges en négatif. Une publication donne l'exercice N et le comparatif N-1 : renseignez les deux lignes. Texte bleu : saisie. Voir « Lisez-moi ».
A4: Ticker | B4: Société | C4: Exercice | D4: Période | E4: Statut | F4: Date de publication | G4: Source (lien ou référence) | H4: Chiffre d'affaires | I4: Valeur ajoutée | J4: EBE (excédent brut d'exploitation) | K4: Résultat d'exploitation | L4: Résultat des activités ordinaires (RAO) | M4: Résultat net | N4: Complétude | O4: Contrôle de cohérence | P4: Var. chiffre d'affaires vs même période N-1 | Q4: Var. valeur ajoutée vs même période N-1 | R4: Var. ebe vs même période N-1 | S4: Var. résultat d'exploitation vs même période N-1 | T4: Var. résultat des activités ordinaires vs même période N-1 | U4: Var. résultat net vs même période N-1
A5: NTLC | B5: =IF(A5="","",IFERROR(VLOOKUP(A5,Titres!$A$2:$B$400,2,FALSE),"Ticker inconnu")) | C5: 2021 | D5: T1 | N5: =IF(A5="","",COUNT(H5:M5)/6) | O5: =IF(COUNT(H5:M5)=0,"",IF(LEN(IF(COUNT(I5,J5)=2,IF(J5>I5+1,"EBE > VA ",""),"")&IF(COUNT(H5,M5)=2,IF(ABS(M5)>ABS(H5),"RN > CA ",""),"")&IF(COUNT(H5,K5)=2,IF(ABS(K5)>ABS(H5),"RE > CA ",""),""))=0,"OK",IF(COUNT(I5,J5)=2,IF(J5>I5+1,"EBE > VA ",""),"")&IF(COUNT(H5,M5)=2,IF(ABS(M5)>ABS(H5),"RN > CA ",""),"")&IF(COUNT(H5,K5)=2,IF(ABS(K5)>ABS(H5),"RE > CA ",""),""))) | P5: =IF(OR($A5="",H5="",$C5=""),"",IF(COUNTIFS($A$5:$A$639,$A5,$C$5:$C$639,$C5-1,$D$5:$D$639,$D5,H$5:H$639,"<>")=0,"",IF(OR(SUMIFS(H$5:H$639,$A$5:$A$639,$A5,$C$5:$C$639,$C5-1,$D$5:$D$639,$D5)=0,H5*SUMIFS(H$5:H$639,$A$5:$A$639,$A5,$C$5:$C$639,$C5-1,$D$5:$D$639,$D5)<0),"n.s.",ABS(H5)/ABS(SUMIFS(H$5:H$639,$A$5:$A$639,$A5,$C$5:$C$639,$C5-1,$D$5:$D$639,$D5))-1))) | Q5: =IF(OR($A5="",I5="",$C5=""),"",IF(COUNTIFS($A$5:$A$639,$A5,$C$5:$C$639,$C5-1,$D$5:$D$639,$D5,I$5:I$639,"<>")=0,"",IF(OR(SUMIFS(I$5:I$639,$A$5:$A$639,$A5,$C$5:$C$639,$C5-1,$D$5:$D$639,$D5)=0,I5*SUMIFS(I$5:I$639,$A$5:$A$639,$A5,$C$5:$C$639,$C5-1,$D$5:$D$639,$D5)<0),"n.s.",ABS(I5)/ABS(SUMIFS(I$5:I$639,$A$5:$A$639,$A5,$C$5:$C$639,$C5-1,$D$5:$D$639,$D5))-1))) | R5: =IF(OR($A5="",J5="",$C5=""),"",IF(COUNTIFS($A$5:$A$639,$A5,$C$5:$C$639,$C5-1,$D$5:$D$639,$D5,J$5:J$639,"<>")=0,"",IF(OR(SUMIFS(J$5:J$639,$A$5:$A$639,$A5,$C$5:$C$639,$C5-1,$D$5:$D$639,$D5)=0,J5*SUMIFS(J$5:J$639,$A$5:$A$639,$A5,$C$5:$C$639,$C5-1,$D$5:$D$639,$D5)<0),"n.s.",ABS(J5)/ABS(SUMIFS(J$5:J$639,$A$5:$A$639,$A5,$C$5:$C$639,$C5-1,$D$5:$D$639,$D5))-1))) | S5: =IF(OR($A5="",K5="",$C5=""),"",IF(COUNTIFS($A$5:$A$639,$A5,$C$5:$C$639,$C5-1,$D$5:$D$639,$D5,K$5:K$639,"<>")=0,"",IF(OR(SUMIFS(K$5:K$639,$A$5:$A$639,$A5,$C$5:$C$639,$C5-1,$D$5:$D$639,$D5)=0,K5*SUMIFS(K$5:K$639,$A$5:$A$639,$A5,$C$5:$C$639,$C5-1,$D$5:$D$639,$D5)<0),"n.s.",ABS(K5)/ABS(SUMIFS(K$5:K$639,$A$5:$A$639,$A5,$C$5:$C$639,$C5-1,$D$5:$D$639,$D5))-1))) | T5: =IF(OR($A5="",L5="",$C5=""),"",IF(COUNTIFS($A$5:$A$639,$A5,$C$5:$C$639,$C5-1,$D$5:$D$639,$D5,L$5:L$639,"<>")=0,"",IF(OR(SUMIFS(L$5:L$639,$A$5:$A$639,$A5,$C$5:$C$639,$C5-1,$D$5:$D$639,$D5)=0,L5*SUMIFS(L$5:L$639,$A$5:$A$639,$A5,$C$5:$C$639,$C5-1,$D$5:$D$639,$D5)<0),"n.s.",ABS(L5)/ABS(SUMIFS(L$5:L$639,$A$5:$A$639,$A5,$C$5:$C$639,$C5-1,$D$5:$D$639,$D5))-1))) | U5: =IF(OR($A5="",M5="",$C5=""),"",IF(COUNTIFS($A$5:$A$639,$A5,$C$5:$C$639,$C5-1,$D$5:$D$639,$D5,M$5:M$639,"<>")=0,"",IF(OR(SUMIFS(M$5:M$639,$A$5:$A$639,$A5,$C$5:$C$639,$C5-1,$D$5:$D$639,$D5)=0,M5*SUMIFS(M$5:M$639,$A$5:$A$639,$A5,$C$5:$C$639,$C5-1,$D$5:$D$639,$D5)<0),"n.s.",ABS(M5)/ABS(SUMIFS(M$5:M$639,$A$5:$A$639,$A5,$C$5:$C$639,$C5-1,$D$5:$D$639,$D5))-1)))
A6: NTLC | B6: =IF(A6="","",IFERROR(VLOOKUP(A6,Titres!$A$2:$B$400,2,FALSE),"Ticker inconnu")) | C6: 2021 | D6: S1 | N6: =IF(A6="","",COUNT(H6:M6)/6) | O6: =IF(COUNT(H6:M6)=0,"",IF(LEN(IF(COUNT(I6,J6)=2,IF(J6>I6+1,"EBE > VA ",""),"")&IF(COUNT(H6,M6)=2,IF(ABS(M6)>ABS(H6),"RN > CA ",""),"")&IF(COUNT(H6,K6)=2,IF(ABS(K6)>ABS(H6),"RE > CA ",""),""))=0,"OK",IF(COUNT(I6,J6)=2,IF(J6>I6+1,"EBE > VA ",""),"")&IF(COUNT(H6,M6)=2,IF(ABS(M6)>ABS(H6),"RN > CA ",""),"")&IF(COUNT(H6,K6)=2,IF(ABS(K6)>ABS(H6),"RE > CA ",""),""))) | P6: =IF(OR($A6="",H6="",$C6=""),"",IF(COUNTIFS($A$5:$A$639,$A6,$C$5:$C$639,$C6-1,$D$5:$D$639,$D6,H$5:H$639,"<>")=0,"",IF(OR(SUMIFS(H$5:H$639,$A$5:$A$639,$A6,$C$5:$C$639,$C6-1,$D$5:$D$639,$D6)=0,H6*SUMIFS(H$5:H$639,$A$5:$A$639,$A6,$C$5:$C$639,$C6-1,$D$5:$D$639,$D6)<0),"n.s.",ABS(H6)/ABS(SUMIFS(H$5:H$639,$A$5:$A$639,$A6,$C$5:$C$639,$C6-1,$D$5:$D$639,$D6))-1))) | Q6: =IF(OR($A6="",I6="",$C6=""),"",IF(COUNTIFS($A$5:$A$639,$A6,$C$5:$C$639,$C6-1,$D$5:$D$639,$D6,I$5:I$639,"<>")=0,"",IF(OR(SUMIFS(I$5:I$639,$A$5:$A$639,$A6,$C$5:$C$639,$C6-1,$D$5:$D$639,$D6)=0,I6*SUMIFS(I$5:I$639,$A$5:$A$639,$A6,$C$5:$C$639,$C6-1,$D$5:$D$639,$D6)<0),"n.s.",ABS(I6)/ABS(SUMIFS(I$5:I$639,$A$5:$A$639,$A6,$C$5:$C$639,$C6-1,$D$5:$D$639,$D6))-1))) | R6: =IF(OR($A6="",J6="",$C6=""),"",IF(COUNTIFS($A$5:$A$639,$A6,$C$5:$C$639,$C6-1,$D$5:$D$639,$D6,J$5:J$639,"<>")=0,"",IF(OR(SUMIFS(J$5:J$639,$A$5:$A$639,$A6,$C$5:$C$639,$C6-1,$D$5:$D$639,$D6)=0,J6*SUMIFS(J$5:J$639,$A$5:$A$639,$A6,$C$5:$C$639,$C6-1,$D$5:$D$639,$D6)<0),"n.s.",ABS(J6)/ABS(SUMIFS(J$5:J$639,$A$5:$A$639,$A6,$C$5:$C$639,$C6-1,$D$5:$D$639,$D6))-1))) | S6: =IF(OR($A6="",K6="",$C6=""),"",IF(COUNTIFS($A$5:$A$639,$A6,$C$5:$C$639,$C6-1,$D$5:$D$639,$D6,K$5:K$639,"<>")=0,"",IF(OR(SUMIFS(K$5:K$639,$A$5:$A$639,$A6,$C$5:$C$639,$C6-1,$D$5:$D$639,$D6)=0,K6*SUMIFS(K$5:K$639,$A$5:$A$639,$A6,$C$5:$C$639,$C6-1,$D$5:$D$639,$D6)<0),"n.s.",ABS(K6)/ABS(SUMIFS(K$5:K$639,$A$5:$A$639,$A6,$C$5:$C$639,$C6-1,$D$5:$D$639,$D6))-1))) | T6: =IF(OR($A6="",L6="",$C6=""),"",IF(COUNTIFS($A$5:$A$639,$A6,$C$5:$C$639,$C6-1,$D$5:$D$639,$D6,L$5:L$639,"<>")=0,"",IF(OR(SUMIFS(L$5:L$639,$A$5:$A$639,$A6,$C$5:$C$639,$C6-1,$D$5:$D$639,$D6)=0,L6*SUMIFS(L$5:L$639,$A$5:$A$639,$A6,$C$5:$C$639,$C6-1,$D$5:$D$639,$D6)<0),"n.s.",ABS(L6)/ABS(SUMIFS(L$5:L$639,$A$5:$A$639,$A6,$C$5:$C$639,$C6-1,$D$5:$D$639,$D6))-1))) | U6: =IF(OR($A6="",M6="",$C6=""),"",IF(COUNTIFS($A$5:$A$639,$A6,$C$5:$C$639,$C6-1,$D$5:$D$639,$D6,M$5:M$639,"<>")=0,"",IF(OR(SUMIFS(M$5:M$639,$A$5:$A$639,$A6,$C$5:$C$639,$C6-1,$D$5:$D$639,$D6)=0,M6*SUMIFS(M$5:M$639,$A$5:$A$639,$A6,$C$5:$C$639,$C6-1,$D$5:$D$639,$D6)<0),"n.s.",ABS(M6)/ABS(SUMIFS(M$5:M$639,$A$5:$A$639,$A6,$C$5:$C$639,$C6-1,$D$5:$D$639,$D6))-1)))
A7: NTLC | B7: =IF(A7="","",IFERROR(VLOOKUP(A7,Titres!$A$2:$B$400,2,FALSE),"Ticker inconnu")) | C7: 2021 | D7: T3 | N7: =IF(A7="","",COUNT(H7:M7)/6) | O7: =IF(COUNT(H7:M7)=0,"",IF(LEN(IF(COUNT(I7,J7)=2,IF(J7>I7+1,"EBE > VA ",""),"")&IF(COUNT(H7,M7)=2,IF(ABS(M7)>ABS(H7),"RN > CA ",""),"")&IF(COUNT(H7,K7)=2,IF(ABS(K7)>ABS(H7),"RE > CA ",""),""))=0,"OK",IF(COUNT(I7,J7)=2,IF(J7>I7+1,"EBE > VA ",""),"")&IF(COUNT(H7,M7)=2,IF(ABS(M7)>ABS(H7),"RN > CA ",""),"")&IF(COUNT(H7,K7)=2,IF(ABS(K7)>ABS(H7),"RE > CA ",""),""))) | P7: =IF(OR($A7="",H7="",$C7=""),"",IF(COUNTIFS($A$5:$A$639,$A7,$C$5:$C$639,$C7-1,$D$5:$D$639,$D7,H$5:H$639,"<>")=0,"",IF(OR(SUMIFS(H$5:H$639,$A$5:$A$639,$A7,$C$5:$C$639,$C7-1,$D$5:$D$639,$D7)=0,H7*SUMIFS(H$5:H$639,$A$5:$A$639,$A7,$C$5:$C$639,$C7-1,$D$5:$D$639,$D7)<0),"n.s.",ABS(H7)/ABS(SUMIFS(H$5:H$639,$A$5:$A$639,$A7,$C$5:$C$639,$C7-1,$D$5:$D$639,$D7))-1))) | Q7: =IF(OR($A7="",I7="",$C7=""),"",IF(COUNTIFS($A$5:$A$639,$A7,$C$5:$C$639,$C7-1,$D$5:$D$639,$D7,I$5:I$639,"<>")=0,"",IF(OR(SUMIFS(I$5:I$639,$A$5:$A$639,$A7,$C$5:$C$639,$C7-1,$D$5:$D$639,$D7)=0,I7*SUMIFS(I$5:I$639,$A$5:$A$639,$A7,$C$5:$C$639,$C7-1,$D$5:$D$639,$D7)<0),"n.s.",ABS(I7)/ABS(SUMIFS(I$5:I$639,$A$5:$A$639,$A7,$C$5:$C$639,$C7-1,$D$5:$D$639,$D7))-1))) | R7: =IF(OR($A7="",J7="",$C7=""),"",IF(COUNTIFS($A$5:$A$639,$A7,$C$5:$C$639,$C7-1,$D$5:$D$639,$D7,J$5:J$639,"<>")=0,"",IF(OR(SUMIFS(J$5:J$639,$A$5:$A$639,$A7,$C$5:$C$639,$C7-1,$D$5:$D$639,$D7)=0,J7*SUMIFS(J$5:J$639,$A$5:$A$639,$A7,$C$5:$C$639,$C7-1,$D$5:$D$639,$D7)<0),"n.s.",ABS(J7)/ABS(SUMIFS(J$5:J$639,$A$5:$A$639,$A7,$C$5:$C$639,$C7-1,$D$5:$D$639,$D7))-1))) | S7: =IF(OR($A7="",K7="",$C7=""),"",IF(COUNTIFS($A$5:$A$639,$A7,$C$5:$C$639,$C7-1,$D$5:$D$639,$D7,K$5:K$639,"<>")=0,"",IF(OR(SUMIFS(K$5:K$639,$A$5:$A$639,$A7,$C$5:$C$639,$C7-1,$D$5:$D$639,$D7)=0,K7*SUMIFS(K$5:K$639,$A$5:$A$639,$A7,$C$5:$C$639,$C7-1,$D$5:$D$639,$D7)<0),"n.s.",ABS(K7)/ABS(SUMIFS(K$5:K$639,$A$5:$A$639,$A7,$C$5:$C$639,$C7-1,$D$5:$D$639,$D7))-1))) | T7: =IF(OR($A7="",L7="",$C7=""),"",IF(COUNTIFS($A$5:$A$639,$A7,$C$5:$C$639,$C7-1,$D$5:$D$639,$D7,L$5:L$639,"<>")=0,"",IF(OR(SUMIFS(L$5:L$639,$A$5:$A$639,$A7,$C$5:$C$639,$C7-1,$D$5:$D$639,$D7)=0,L7*SUMIFS(L$5:L$639,$A$5:$A$639,$A7,$C$5:$C$639,$C7-1,$D$5:$D$639,$D7)<0),"n.s.",ABS(L7)/ABS(SUMIFS(L$5:L$639,$A$5:$A$639,$A7,$C$5:$C$639,$C7-1,$D$5:$D$639,$D7))-1))) | U7: =IF(OR($A7="",M7="",$C7=""),"",IF(COUNTIFS($A$5:$A$639,$A7,$C$5:$C$639,$C7-1,$D$5:$D$639,$D7,M$5:M$639,"<>")=0,"",IF(OR(SUMIFS(M$5:M$639,$A$5:$A$639,$A7,$C$5:$C$639,$C7-1,$D$5:$D$639,$D7)=0,M7*SUMIFS(M$5:M$639,$A$5:$A$639,$A7,$C$5:$C$639,$C7-1,$D$5:$D$639,$D7)<0),"n.s.",ABS(M7)/ABS(SUMIFS(M$5:M$639,$A$5:$A$639,$A7,$C$5:$C$639,$C7-1,$D$5:$D$639,$D7))-1)))
A8: NTLC | B8: =IF(A8="","",IFERROR(VLOOKUP(A8,Titres!$A$2:$B$400,2,FALSE),"Ticker inconnu")) | C8: 2022 | D8: T1 | N8: =IF(A8="","",COUNT(H8:M8)/6) | O8: =IF(COUNT(H8:M8)=0,"",IF(LEN(IF(COUNT(I8,J8)=2,IF(J8>I8+1,"EBE > VA ",""),"")&IF(COUNT(H8,M8)=2,IF(ABS(M8)>ABS(H8),"RN > CA ",""),"")&IF(COUNT(H8,K8)=2,IF(ABS(K8)>ABS(H8),"RE > CA ",""),""))=0,"OK",IF(COUNT(I8,J8)=2,IF(J8>I8+1,"EBE > VA ",""),"")&IF(COUNT(H8,M8)=2,IF(ABS(M8)>ABS(H8),"RN > CA ",""),"")&IF(COUNT(H8,K8)=2,IF(ABS(K8)>ABS(H8),"RE > CA ",""),""))) | P8: =IF(OR($A8="",H8="",$C8=""),"",IF(COUNTIFS($A$5:$A$639,$A8,$C$5:$C$639,$C8-1,$D$5:$D$639,$D8,H$5:H$639,"<>")=0,"",IF(OR(SUMIFS(H$5:H$639,$A$5:$A$639,$A8,$C$5:$C$639,$C8-1,$D$5:$D$639,$D8)=0,H8*SUMIFS(H$5:H$639,$A$5:$A$639,$A8,$C$5:$C$639,$C8-1,$D$5:$D$639,$D8)<0),"n.s.",ABS(H8)/ABS(SUMIFS(H$5:H$639,$A$5:$A$639,$A8,$C$5:$C$639,$C8-1,$D$5:$D$639,$D8))-1))) | Q8: =IF(OR($A8="",I8="",$C8=""),"",IF(COUNTIFS($A$5:$A$639,$A8,$C$5:$C$639,$C8-1,$D$5:$D$639,$D8,I$5:I$639,"<>")=0,"",IF(OR(SUMIFS(I$5:I$639,$A$5:$A$639,$A8,$C$5:$C$639,$C8-1,$D$5:$D$639,$D8)=0,I8*SUMIFS(I$5:I$639,$A$5:$A$639,$A8,$C$5:$C$639,$C8-1,$D$5:$D$639,$D8)<0),"n.s.",ABS(I8)/ABS(SUMIFS(I$5:I$639,$A$5:$A$639,$A8,$C$5:$C$639,$C8-1,$D$5:$D$639,$D8))-1))) | R8: =IF(OR($A8="",J8="",$C8=""),"",IF(COUNTIFS($A$5:$A$639,$A8,$C$5:$C$639,$C8-1,$D$5:$D$639,$D8,J$5:J$639,"<>")=0,"",IF(OR(SUMIFS(J$5:J$639,$A$5:$A$639,$A8,$C$5:$C$639,$C8-1,$D$5:$D$639,$D8)=0,J8*SUMIFS(J$5:J$639,$A$5:$A$639,$A8,$C$5:$C$639,$C8-1,$D$5:$D$639,$D8)<0),"n.s.",ABS(J8)/ABS(SUMIFS(J$5:J$639,$A$5:$A$639,$A8,$C$5:$C$639,$C8-1,$D$5:$D$639,$D8))-1))) | S8: =IF(OR($A8="",K8="",$C8=""),"",IF(COUNTIFS($A$5:$A$639,$A8,$C$5:$C$639,$C8-1,$D$5:$D$639,$D8,K$5:K$639,"<>")=0,"",IF(OR(SUMIFS(K$5:K$639,$A$5:$A$639,$A8,$C$5:$C$639,$C8-1,$D$5:$D$639,$D8)=0,K8*SUMIFS(K$5:K$639,$A$5:$A$639,$A8,$C$5:$C$639,$C8-1,$D$5:$D$639,$D8)<0),"n.s.",ABS(K8)/ABS(SUMIFS(K$5:K$639,$A$5:$A$639,$A8,$C$5:$C$639,$C8-1,$D$5:$D$639,$D8))-1))) | T8: =IF(OR($A8="",L8="",$C8=""),"",IF(COUNTIFS($A$5:$A$639,$A8,$C$5:$C$639,$C8-1,$D$5:$D$639,$D8,L$5:L$639,"<>")=0,"",IF(OR(SUMIFS(L$5:L$639,$A$5:$A$639,$A8,$C$5:$C$639,$C8-1,$D$5:$D$639,$D8)=0,L8*SUMIFS(L$5:L$639,$A$5:$A$639,$A8,$C$5:$C$639,$C8-1,$D$5:$D$639,$D8)<0),"n.s.",ABS(L8)/ABS(SUMIFS(L$5:L$639,$A$5:$A$639,$A8,$C$5:$C$639,$C8-1,$D$5:$D$639,$D8))-1))) | U8: =IF(OR($A8="",M8="",$C8=""),"",IF(COUNTIFS($A$5:$A$639,$A8,$C$5:$C$639,$C8-1,$D$5:$D$639,$D8,M$5:M$639,"<>")=0,"",IF(OR(SUMIFS(M$5:M$639,$A$5:$A$639,$A8,$C$5:$C$639,$C8-1,$D$5:$D$639,$D8)=0,M8*SUMIFS(M$5:M$639,$A$5:$A$639,$A8,$C$5:$C$639,$C8-1,$D$5:$D$639,$D8)<0),"n.s.",ABS(M8)/ABS(SUMIFS(M$5:M$639,$A$5:$A$639,$A8,$C$5:$C$639,$C8-1,$D$5:$D$639,$D8))-1)))
A9: NTLC | B9: =IF(A9="","",IFERROR(VLOOKUP(A9,Titres!$A$2:$B$400,2,FALSE),"Ticker inconnu")) | C9: 2022 | D9: S1 | N9: =IF(A9="","",COUNT(H9:M9)/6) | O9: =IF(COUNT(H9:M9)=0,"",IF(LEN(IF(COUNT(I9,J9)=2,IF(J9>I9+1,"EBE > VA ",""),"")&IF(COUNT(H9,M9)=2,IF(ABS(M9)>ABS(H9),"RN > CA ",""),"")&IF(COUNT(H9,K9)=2,IF(ABS(K9)>ABS(H9),"RE > CA ",""),""))=0,"OK",IF(COUNT(I9,J9)=2,IF(J9>I9+1,"EBE > VA ",""),"")&IF(COUNT(H9,M9)=2,IF(ABS(M9)>ABS(H9),"RN > CA ",""),"")&IF(COUNT(H9,K9)=2,IF(ABS(K9)>ABS(H9),"RE > CA ",""),""))) | P9: =IF(OR($A9="",H9="",$C9=""),"",IF(COUNTIFS($A$5:$A$639,$A9,$C$5:$C$639,$C9-1,$D$5:$D$639,$D9,H$5:H$639,"<>")=0,"",IF(OR(SUMIFS(H$5:H$639,$A$5:$A$639,$A9,$C$5:$C$639,$C9-1,$D$5:$D$639,$D9)=0,H9*SUMIFS(H$5:H$639,$A$5:$A$639,$A9,$C$5:$C$639,$C9-1,$D$5:$D$639,$D9)<0),"n.s.",ABS(H9)/ABS(SUMIFS(H$5:H$639,$A$5:$A$639,$A9,$C$5:$C$639,$C9-1,$D$5:$D$639,$D9))-1))) | Q9: =IF(OR($A9="",I9="",$C9=""),"",IF(COUNTIFS($A$5:$A$639,$A9,$C$5:$C$639,$C9-1,$D$5:$D$639,$D9,I$5:I$639,"<>")=0,"",IF(OR(SUMIFS(I$5:I$639,$A$5:$A$639,$A9,$C$5:$C$639,$C9-1,$D$5:$D$639,$D9)=0,I9*SUMIFS(I$5:I$639,$A$5:$A$639,$A9,$C$5:$C$639,$C9-1,$D$5:$D$639,$D9)<0),"n.s.",ABS(I9)/ABS(SUMIFS(I$5:I$639,$A$5:$A$639,$A9,$C$5:$C$639,$C9-1,$D$5:$D$639,$D9))-1))) | R9: =IF(OR($A9="",J9="",$C9=""),"",IF(COUNTIFS($A$5:$A$639,$A9,$C$5:$C$639,$C9-1,$D$5:$D$639,$D9,J$5:J$639,"<>")=0,"",IF(OR(SUMIFS(J$5:J$639,$A$5:$A$639,$A9,$C$5:$C$639,$C9-1,$D$5:$D$639,$D9)=0,J9*SUMIFS(J$5:J$639,$A$5:$A$639,$A9,$C$5:$C$639,$C9-1,$D$5:$D$639,$D9)<0),"n.s.",ABS(J9)/ABS(SUMIFS(J$5:J$639,$A$5:$A$639,$A9,$C$5:$C$639,$C9-1,$D$5:$D$639,$D9))-1))) | S9: =IF(OR($A9="",K9="",$C9=""),"",IF(COUNTIFS($A$5:$A$639,$A9,$C$5:$C$639,$C9-1,$D$5:$D$639,$D9,K$5:K$639,"<>")=0,"",IF(OR(SUMIFS(K$5:K$639,$A$5:$A$639,$A9,$C$5:$C$639,$C9-1,$D$5:$D$639,$D9)=0,K9*SUMIFS(K$5:K$639,$A$5:$A$639,$A9,$C$5:$C$639,$C9-1,$D$5:$D$639,$D9)<0),"n.s.",ABS(K9)/ABS(SUMIFS(K$5:K$639,$A$5:$A$639,$A9,$C$5:$C$639,$C9-1,$D$5:$D$639,$D9))-1))) | T9: =IF(OR($A9="",L9="",$C9=""),"",IF(COUNTIFS($A$5:$A$639,$A9,$C$5:$C$639,$C9-1,$D$5:$D$639,$D9,L$5:L$639,"<>")=0,"",IF(OR(SUMIFS(L$5:L$639,$A$5:$A$639,$A9,$C$5:$C$639,$C9-1,$D$5:$D$639,$D9)=0,L9*SUMIFS(L$5:L$639,$A$5:$A$639,$A9,$C$5:$C$639,$C9-1,$D$5:$D$639,$D9)<0),"n.s.",ABS(L9)/ABS(SUMIFS(L$5:L$639,$A$5:$A$639,$A9,$C$5:$C$639,$C9-1,$D$5:$D$639,$D9))-1))) | U9: =IF(OR($A9="",M9="",$C9=""),"",IF(COUNTIFS($A$5:$A$639,$A9,$C$5:$C$639,$C9-1,$D$5:$D$639,$D9,M$5:M$639,"<>")=0,"",IF(OR(SUMIFS(M$5:M$639,$A$5:$A$639,$A9,$C$5:$C$639,$C9-1,$D$5:$D$639,$D9)=0,M9*SUMIFS(M$5:M$639,$A$5:$A$639,$A9,$C$5:$C$639,$C9-1,$D$5:$D$639,$D9)<0),"n.s.",ABS(M9)/ABS(SUMIFS(M$5:M$639,$A$5:$A$639,$A9,$C$5:$C$639,$C9-1,$D$5:$D$639,$D9))-1)))
A10: NTLC | B10: =IF(A10="","",IFERROR(VLOOKUP(A10,Titres!$A$2:$B$400,2,FALSE),"Ticker inconnu")) | C10: 2022 | D10: T3 | N10: =IF(A10="","",COUNT(H10:M10)/6) | O10: =IF(COUNT(H10:M10)=0,"",IF(LEN(IF(COUNT(I10,J10)=2,IF(J10>I10+1,"EBE > VA ",""),"")&IF(COUNT(H10,M10)=2,IF(ABS(M10)>ABS(H10),"RN > CA ",""),"")&IF(COUNT(H10,K10)=2,IF(ABS(K10)>ABS(H10),"RE > CA ",""),""))=0,"OK",IF(COUNT(I10,J10)=2,IF(J10>I10+1,"EBE > VA ",""),"")&IF(COUNT(H10,M10)=2,IF(ABS(M10)>ABS(H10),"RN > CA ",""),"")&IF(COUNT(H10,K10)=2,IF(ABS(K10)>ABS(H10),"RE > CA ",""),""))) | P10: =IF(OR($A10="",H10="",$C10=""),"",IF(COUNTIFS($A$5:$A$639,$A10,$C$5:$C$639,$C10-1,$D$5:$D$639,$D10,H$5:H$639,"<>")=0,"",IF(OR(SUMIFS(H$5:H$639,$A$5:$A$639,$A10,$C$5:$C$639,$C10-1,$D$5:$D$639,$D10)=0,H10*SUMIFS(H$5:H$639,$A$5:$A$639,$A10,$C$5:$C$639,$C10-1,$D$5:$D$639,$D10)<0),"n.s.",ABS(H10)/ABS(SUMIFS(H$5:H$639,$A$5:$A$639,$A10,$C$5:$C$639,$C10-1,$D$5:$D$639,$D10))-1))) | Q10: =IF(OR($A10="",I10="",$C10=""),"",IF(COUNTIFS($A$5:$A$639,$A10,$C$5:$C$639,$C10-1,$D$5:$D$639,$D10,I$5:I$639,"<>")=0,"",IF(OR(SUMIFS(I$5:I$639,$A$5:$A$639,$A10,$C$5:$C$639,$C10-1,$D$5:$D$639,$D10)=0,I10*SUMIFS(I$5:I$639,$A$5:$A$639,$A10,$C$5:$C$639,$C10-1,$D$5:$D$639,$D10)<0),"n.s.",ABS(I10)/ABS(SUMIFS(I$5:I$639,$A$5:$A$639,$A10,$C$5:$C$639,$C10-1,$D$5:$D$639,$D10))-1))) | R10: =IF(OR($A10="",J10="",$C10=""),"",IF(COUNTIFS($A$5:$A$639,$A10,$C$5:$C$639,$C10-1,$D$5:$D$639,$D10,J$5:J$639,"<>")=0,"",IF(OR(SUMIFS(J$5:J$639,$A$5:$A$639,$A10,$C$5:$C$639,$C10-1,$D$5:$D$639,$D10)=0,J10*SUMIFS(J$5:J$639,$A$5:$A$639,$A10,$C$5:$C$639,$C10-1,$D$5:$D$639,$D10)<0),"n.s.",ABS(J10)/ABS(SUMIFS(J$5:J$639,$A$5:$A$639,$A10,$C$5:$C$639,$C10-1,$D$5:$D$639,$D10))-1))) | S10: =IF(OR($A10="",K10="",$C10=""),"",IF(COUNTIFS($A$5:$A$639,$A10,$C$5:$C$639,$C10-1,$D$5:$D$639,$D10,K$5:K$639,"<>")=0,"",IF(OR(SUMIFS(K$5:K$639,$A$5:$A$639,$A10,$C$5:$C$639,$C10-1,$D$5:$D$639,$D10)=0,K10*SUMIFS(K$5:K$639,$A$5:$A$639,$A10,$C$5:$C$639,$C10-1,$D$5:$D$639,$D10)<0),"n.s.",ABS(K10)/ABS(SUMIFS(K$5:K$639,$A$5:$A$639,$A10,$C$5:$C$639,$C10-1,$D$5:$D$639,$D10))-1))) | T10: =IF(OR($A10="",L10="",$C10=""),"",IF(COUNTIFS($A$5:$A$639,$A10,$C$5:$C$639,$C10-1,$D$5:$D$639,$D10,L$5:L$639,"<>")=0,"",IF(OR(SUMIFS(L$5:L$639,$A$5:$A$639,$A10,$C$5:$C$639,$C10-1,$D$5:$D$639,$D10)=0,L10*SUMIFS(L$5:L$639,$A$5:$A$639,$A10,$C$5:$C$639,$C10-1,$D$5:$D$639,$D10)<0),"n.s.",ABS(L10)/ABS(SUMIFS(L$5:L$639,$A$5:$A$639,$A10,$C$5:$C$639,$C10-1,$D$5:$D$639,$D10))-1))) | U10: =IF(OR($A10="",M10="",$C10=""),"",IF(COUNTIFS($A$5:$A$639,$A10,$C$5:$C$639,$C10-1,$D$5:$D$639,$D10,M$5:M$639,"<>")=0,"",IF(OR(SUMIFS(M$5:M$639,$A$5:$A$639,$A10,$C$5:$C$639,$C10-1,$D$5:$D$639,$D10)=0,M10*SUMIFS(M$5:M$639,$A$5:$A$639,$A10,$C$5:$C$639,$C10-1,$D$5:$D$639,$D10)<0),"n.s.",ABS(M10)/ABS(SUMIFS(M$5:M$639,$A$5:$A$639,$A10,$C$5:$C$639,$C10-1,$D$5:$D$639,$D10))-1)))
A11: NTLC | B11: =IF(A11="","",IFERROR(VLOOKUP(A11,Titres!$A$2:$B$400,2,FALSE),"Ticker inconnu")) | C11: 2023 | D11: T1 | N11: =IF(A11="","",COUNT(H11:M11)/6) | O11: =IF(COUNT(H11:M11)=0,"",IF(LEN(IF(COUNT(I11,J11)=2,IF(J11>I11+1,"EBE > VA ",""),"")&IF(COUNT(H11,M11)=2,IF(ABS(M11)>ABS(H11),"RN > CA ",""),"")&IF(COUNT(H11,K11)=2,IF(ABS(K11)>ABS(H11),"RE > CA ",""),""))=0,"OK",IF(COUNT(I11,J11)=2,IF(J11>I11+1,"EBE > VA ",""),"")&IF(COUNT(H11,M11)=2,IF(ABS(M11)>ABS(H11),"RN > CA ",""),"")&IF(COUNT(H11,K11)=2,IF(ABS(K11)>ABS(H11),"RE > CA ",""),""))) | P11: =IF(OR($A11="",H11="",$C11=""),"",IF(COUNTIFS($A$5:$A$639,$A11,$C$5:$C$639,$C11-1,$D$5:$D$639,$D11,H$5:H$639,"<>")=0,"",IF(OR(SUMIFS(H$5:H$639,$A$5:$A$639,$A11,$C$5:$C$639,$C11-1,$D$5:$D$639,$D11)=0,H11*SUMIFS(H$5:H$639,$A$5:$A$639,$A11,$C$5:$C$639,$C11-1,$D$5:$D$639,$D11)<0),"n.s.",ABS(H11)/ABS(SUMIFS(H$5:H$639,$A$5:$A$639,$A11,$C$5:$C$639,$C11-1,$D$5:$D$639,$D11))-1))) | Q11: =IF(OR($A11="",I11="",$C11=""),"",IF(COUNTIFS($A$5:$A$639,$A11,$C$5:$C$639,$C11-1,$D$5:$D$639,$D11,I$5:I$639,"<>")=0,"",IF(OR(SUMIFS(I$5:I$639,$A$5:$A$639,$A11,$C$5:$C$639,$C11-1,$D$5:$D$639,$D11)=0,I11*SUMIFS(I$5:I$639,$A$5:$A$639,$A11,$C$5:$C$639,$C11-1,$D$5:$D$639,$D11)<0),"n.s.",ABS(I11)/ABS(SUMIFS(I$5:I$639,$A$5:$A$639,$A11,$C$5:$C$639,$C11-1,$D$5:$D$639,$D11))-1))) | R11: =IF(OR($A11="",J11="",$C11=""),"",IF(COUNTIFS($A$5:$A$639,$A11,$C$5:$C$639,$C11-1,$D$5:$D$639,$D11,J$5:J$639,"<>")=0,"",IF(OR(SUMIFS(J$5:J$639,$A$5:$A$639,$A11,$C$5:$C$639,$C11-1,$D$5:$D$639,$D11)=0,J11*SUMIFS(J$5:J$639,$A$5:$A$639,$A11,$C$5:$C$639,$C11-1,$D$5:$D$639,$D11)<0),"n.s.",ABS(J11)/ABS(SUMIFS(J$5:J$639,$A$5:$A$639,$A11,$C$5:$C$639,$C11-1,$D$5:$D$639,$D11))-1))) | S11: =IF(OR($A11="",K11="",$C11=""),"",IF(COUNTIFS($A$5:$A$639,$A11,$C$5:$C$639,$C11-1,$D$5:$D$639,$D11,K$5:K$639,"<>")=0,"",IF(OR(SUMIFS(K$5:K$639,$A$5:$A$639,$A11,$C$5:$C$639,$C11-1,$D$5:$D$639,$D11)=0,K11*SUMIFS(K$5:K$639,$A$5:$A$639,$A11,$C$5:$C$639,$C11-1,$D$5:$D$639,$D11)<0),"n.s.",ABS(K11)/ABS(SUMIFS(K$5:K$639,$A$5:$A$639,$A11,$C$5:$C$639,$C11-1,$D$5:$D$639,$D11))-1))) | T11: =IF(OR($A11="",L11="",$C11=""),"",IF(COUNTIFS($A$5:$A$639,$A11,$C$5:$C$639,$C11-1,$D$5:$D$639,$D11,L$5:L$639,"<>")=0,"",IF(OR(SUMIFS(L$5:L$639,$A$5:$A$639,$A11,$C$5:$C$639,$C11-1,$D$5:$D$639,$D11)=0,L11*SUMIFS(L$5:L$639,$A$5:$A$639,$A11,$C$5:$C$639,$C11-1,$D$5:$D$639,$D11)<0),"n.s.",ABS(L11)/ABS(SUMIFS(L$5:L$639,$A$5:$A$639,$A11,$C$5:$C$639,$C11-1,$D$5:$D$639,$D11))-1))) | U11: =IF(OR($A11="",M11="",$C11=""),"",IF(COUNTIFS($A$5:$A$639,$A11,$C$5:$C$639,$C11-1,$D$5:$D$639,$D11,M$5:M$639,"<>")=0,"",IF(OR(SUMIFS(M$5:M$639,$A$5:$A$639,$A11,$C$5:$C$639,$C11-1,$D$5:$D$639,$D11)=0,M11*SUMIFS(M$5:M$639,$A$5:$A$639,$A11,$C$5:$C$639,$C11-1,$D$5:$D$639,$D11)<0),"n.s.",ABS(M11)/ABS(SUMIFS(M$5:M$639,$A$5:$A$639,$A11,$C$5:$C$639,$C11-1,$D$5:$D$639,$D11))-1)))
A12: NTLC | B12: =IF(A12="","",IFERROR(VLOOKUP(A12,Titres!$A$2:$B$400,2,FALSE),"Ticker inconnu")) | C12: 2023 | D12: S1 | N12: =IF(A12="","",COUNT(H12:M12)/6) | O12: =IF(COUNT(H12:M12)=0,"",IF(LEN(IF(COUNT(I12,J12)=2,IF(J12>I12+1,"EBE > VA ",""),"")&IF(COUNT(H12,M12)=2,IF(ABS(M12)>ABS(H12),"RN > CA ",""),"")&IF(COUNT(H12,K12)=2,IF(ABS(K12)>ABS(H12),"RE > CA ",""),""))=0,"OK",IF(COUNT(I12,J12)=2,IF(J12>I12+1,"EBE > VA ",""),"")&IF(COUNT(H12,M12)=2,IF(ABS(M12)>ABS(H12),"RN > CA ",""),"")&IF(COUNT(H12,K12)=2,IF(ABS(K12)>ABS(H12),"RE > CA ",""),""))) | P12: =IF(OR($A12="",H12="",$C12=""),"",IF(COUNTIFS($A$5:$A$639,$A12,$C$5:$C$639,$C12-1,$D$5:$D$639,$D12,H$5:H$639,"<>")=0,"",IF(OR(SUMIFS(H$5:H$639,$A$5:$A$639,$A12,$C$5:$C$639,$C12-1,$D$5:$D$639,$D12)=0,H12*SUMIFS(H$5:H$639,$A$5:$A$639,$A12,$C$5:$C$639,$C12-1,$D$5:$D$639,$D12)<0),"n.s.",ABS(H12)/ABS(SUMIFS(H$5:H$639,$A$5:$A$639,$A12,$C$5:$C$639,$C12-1,$D$5:$D$639,$D12))-1))) | Q12: =IF(OR($A12="",I12="",$C12=""),"",IF(COUNTIFS($A$5:$A$639,$A12,$C$5:$C$639,$C12-1,$D$5:$D$639,$D12,I$5:I$639,"<>")=0,"",IF(OR(SUMIFS(I$5:I$639,$A$5:$A$639,$A12,$C$5:$C$639,$C12-1,$D$5:$D$639,$D12)=0,I12*SUMIFS(I$5:I$639,$A$5:$A$639,$A12,$C$5:$C$639,$C12-1,$D$5:$D$639,$D12)<0),"n.s.",ABS(I12)/ABS(SUMIFS(I$5:I$639,$A$5:$A$639,$A12,$C$5:$C$639,$C12-1,$D$5:$D$639,$D12))-1))) | R12: =IF(OR($A12="",J12="",$C12=""),"",IF(COUNTIFS($A$5:$A$639,$A12,$C$5:$C$639,$C12-1,$D$5:$D$639,$D12,J$5:J$639,"<>")=0,"",IF(OR(SUMIFS(J$5:J$639,$A$5:$A$639,$A12,$C$5:$C$639,$C12-1,$D$5:$D$639,$D12)=0,J12*SUMIFS(J$5:J$639,$A$5:$A$639,$A12,$C$5:$C$639,$C12-1,$D$5:$D$639,$D12)<0),"n.s.",ABS(J12)/ABS(SUMIFS(J$5:J$639,$A$5:$A$639,$A12,$C$5:$C$639,$C12-1,$D$5:$D$639,$D12))-1))) | S12: =IF(OR($A12="",K12="",$C12=""),"",IF(COUNTIFS($A$5:$A$639,$A12,$C$5:$C$639,$C12-1,$D$5:$D$639,$D12,K$5:K$639,"<>")=0,"",IF(OR(SUMIFS(K$5:K$639,$A$5:$A$639,$A12,$C$5:$C$639,$C12-1,$D$5:$D$639,$D12)=0,K12*SUMIFS(K$5:K$639,$A$5:$A$639,$A12,$C$5:$C$639,$C12-1,$D$5:$D$639,$D12)<0),"n.s.",ABS(K12)/ABS(SUMIFS(K$5:K$639,$A$5:$A$639,$A12,$C$5:$C$639,$C12-1,$D$5:$D$639,$D12))-1))) | T12: =IF(OR($A12="",L12="",$C12=""),"",IF(COUNTIFS($A$5:$A$639,$A12,$C$5:$C$639,$C12-1,$D$5:$D$639,$D12,L$5:L$639,"<>")=0,"",IF(OR(SUMIFS(L$5:L$639,$A$5:$A$639,$A12,$C$5:$C$639,$C12-1,$D$5:$D$639,$D12)=0,L12*SUMIFS(L$5:L$639,$A$5:$A$639,$A12,$C$5:$C$639,$C12-1,$D$5:$D$639,$D12)<0),"n.s.",ABS(L12)/ABS(SUMIFS(L$5:L$639,$A$5:$A$639,$A12,$C$5:$C$639,$C12-1,$D$5:$D$639,$D12))-1))) | U12: =IF(OR($A12="",M12="",$C12=""),"",IF(COUNTIFS($A$5:$A$639,$A12,$C$5:$C$639,$C12-1,$D$5:$D$639,$D12,M$5:M$639,"<>")=0,"",IF(OR(SUMIFS(M$5:M$639,$A$5:$A$639,$A12,$C$5:$C$639,$C12-1,$D$5:$D$639,$D12)=0,M12*SUMIFS(M$5:M$639,$A$5:$A$639,$A12,$C$5:$C$639,$C12-1,$D$5:$D$639,$D12)<0),"n.s.",ABS(M12)/ABS(SUMIFS(M$5:M$639,$A$5:$A$639,$A12,$C$5:$C$639,$C12-1,$D$5:$D$639,$D12))-1)))
A13: NTLC | B13: =IF(A13="","",IFERROR(VLOOKUP(A13,Titres!$A$2:$B$400,2,FALSE),"Ticker inconnu")) | C13: 2023 | D13: T3 | N13: =IF(A13="","",COUNT(H13:M13)/6) | O13: =IF(COUNT(H13:M13)=0,"",IF(LEN(IF(COUNT(I13,J13)=2,IF(J13>I13+1,"EBE > VA ",""),"")&IF(COUNT(H13,M13)=2,IF(ABS(M13)>ABS(H13),"RN > CA ",""),"")&IF(COUNT(H13,K13)=2,IF(ABS(K13)>ABS(H13),"RE > CA ",""),""))=0,"OK",IF(COUNT(I13,J13)=2,IF(J13>I13+1,"EBE > VA ",""),"")&IF(COUNT(H13,M13)=2,IF(ABS(M13)>ABS(H13),"RN > CA ",""),"")&IF(COUNT(H13,K13)=2,IF(ABS(K13)>ABS(H13),"RE > CA ",""),""))) | P13: =IF(OR($A13="",H13="",$C13=""),"",IF(COUNTIFS($A$5:$A$639,$A13,$C$5:$C$639,$C13-1,$D$5:$D$639,$D13,H$5:H$639,"<>")=0,"",IF(OR(SUMIFS(H$5:H$639,$A$5:$A$639,$A13,$C$5:$C$639,$C13-1,$D$5:$D$639,$D13)=0,H13*SUMIFS(H$5:H$639,$A$5:$A$639,$A13,$C$5:$C$639,$C13-1,$D$5:$D$639,$D13)<0),"n.s.",ABS(H13)/ABS(SUMIFS(H$5:H$639,$A$5:$A$639,$A13,$C$5:$C$639,$C13-1,$D$5:$D$639,$D13))-1))) | Q13: =IF(OR($A13="",I13="",$C13=""),"",IF(COUNTIFS($A$5:$A$639,$A13,$C$5:$C$639,$C13-1,$D$5:$D$639,$D13,I$5:I$639,"<>")=0,"",IF(OR(SUMIFS(I$5:I$639,$A$5:$A$639,$A13,$C$5:$C$639,$C13-1,$D$5:$D$639,$D13)=0,I13*SUMIFS(I$5:I$639,$A$5:$A$639,$A13,$C$5:$C$639,$C13-1,$D$5:$D$639,$D13)<0),"n.s.",ABS(I13)/ABS(SUMIFS(I$5:I$639,$A$5:$A$639,$A13,$C$5:$C$639,$C13-1,$D$5:$D$639,$D13))-1))) | R13: =IF(OR($A13="",J13="",$C13=""),"",IF(COUNTIFS($A$5:$A$639,$A13,$C$5:$C$639,$C13-1,$D$5:$D$639,$D13,J$5:J$639,"<>")=0,"",IF(OR(SUMIFS(J$5:J$639,$A$5:$A$639,$A13,$C$5:$C$639,$C13-1,$D$5:$D$639,$D13)=0,J13*SUMIFS(J$5:J$639,$A$5:$A$639,$A13,$C$5:$C$639,$C13-1,$D$5:$D$639,$D13)<0),"n.s.",ABS(J13)/ABS(SUMIFS(J$5:J$639,$A$5:$A$639,$A13,$C$5:$C$639,$C13-1,$D$5:$D$639,$D13))-1))) | S13: =IF(OR($A13="",K13="",$C13=""),"",IF(COUNTIFS($A$5:$A$639,$A13,$C$5:$C$639,$C13-1,$D$5:$D$639,$D13,K$5:K$639,"<>")=0,"",IF(OR(SUMIFS(K$5:K$639,$A$5:$A$639,$A13,$C$5:$C$639,$C13-1,$D$5:$D$639,$D13)=0,K13*SUMIFS(K$5:K$639,$A$5:$A$639,$A13,$C$5:$C$639,$C13-1,$D$5:$D$639,$D13)<0),"n.s.",ABS(K13)/ABS(SUMIFS(K$5:K$639,$A$5:$A$639,$A13,$C$5:$C$639,$C13-1,$D$5:$D$639,$D13))-1))) | T13: =IF(OR($A13="",L13="",$C13=""),"",IF(COUNTIFS($A$5:$A$639,$A13,$C$5:$C$639,$C13-1,$D$5:$D$639,$D13,L$5:L$639,"<>")=0,"",IF(OR(SUMIFS(L$5:L$639,$A$5:$A$639,$A13,$C$5:$C$639,$C13-1,$D$5:$D$639,$D13)=0,L13*SUMIFS(L$5:L$639,$A$5:$A$639,$A13,$C$5:$C$639,$C13-1,$D$5:$D$639,$D13)<0),"n.s.",ABS(L13)/ABS(SUMIFS(L$5:L$639,$A$5:$A$639,$A13,$C$5:$C$639,$C13-1,$D$5:$D$639,$D13))-1))) | U13: =IF(OR($A13="",M13="",$C13=""),"",IF(COUNTIFS($A$5:$A$639,$A13,$C$5:$C$639,$C13-1,$D$5:$D$639,$D13,M$5:M$639,"<>")=0,"",IF(OR(SUMIFS(M$5:M$639,$A$5:$A$639,$A13,$C$5:$C$639,$C13-1,$D$5:$D$639,$D13)=0,M13*SUMIFS(M$5:M$639,$A$5:$A$639,$A13,$C$5:$C$639,$C13-1,$D$5:$D$639,$D13)<0),"n.s.",ABS(M13)/ABS(SUMIFS(M$5:M$639,$A$5:$A$639,$A13,$C$5:$C$639,$C13-1,$D$5:$D$639,$D13))-1)))
A14: NTLC | B14: =IF(A14="","",IFERROR(VLOOKUP(A14,Titres!$A$2:$B$400,2,FALSE),"Ticker inconnu")) | C14: 2024 | D14: T1 | N14: =IF(A14="","",COUNT(H14:M14)/6) | O14: =IF(COUNT(H14:M14)=0,"",IF(LEN(IF(COUNT(I14,J14)=2,IF(J14>I14+1,"EBE > VA ",""),"")&IF(COUNT(H14,M14)=2,IF(ABS(M14)>ABS(H14),"RN > CA ",""),"")&IF(COUNT(H14,K14)=2,IF(ABS(K14)>ABS(H14),"RE > CA ",""),""))=0,"OK",IF(COUNT(I14,J14)=2,IF(J14>I14+1,"EBE > VA ",""),"")&IF(COUNT(H14,M14)=2,IF(ABS(M14)>ABS(H14),"RN > CA ",""),"")&IF(COUNT(H14,K14)=2,IF(ABS(K14)>ABS(H14),"RE > CA ",""),""))) | P14: =IF(OR($A14="",H14="",$C14=""),"",IF(COUNTIFS($A$5:$A$639,$A14,$C$5:$C$639,$C14-1,$D$5:$D$639,$D14,H$5:H$639,"<>")=0,"",IF(OR(SUMIFS(H$5:H$639,$A$5:$A$639,$A14,$C$5:$C$639,$C14-1,$D$5:$D$639,$D14)=0,H14*SUMIFS(H$5:H$639,$A$5:$A$639,$A14,$C$5:$C$639,$C14-1,$D$5:$D$639,$D14)<0),"n.s.",ABS(H14)/ABS(SUMIFS(H$5:H$639,$A$5:$A$639,$A14,$C$5:$C$639,$C14-1,$D$5:$D$639,$D14))-1))) | Q14: =IF(OR($A14="",I14="",$C14=""),"",IF(COUNTIFS($A$5:$A$639,$A14,$C$5:$C$639,$C14-1,$D$5:$D$639,$D14,I$5:I$639,"<>")=0,"",IF(OR(SUMIFS(I$5:I$639,$A$5:$A$639,$A14,$C$5:$C$639,$C14-1,$D$5:$D$639,$D14)=0,I14*SUMIFS(I$5:I$639,$A$5:$A$639,$A14,$C$5:$C$639,$C14-1,$D$5:$D$639,$D14)<0),"n.s.",ABS(I14)/ABS(SUMIFS(I$5:I$639,$A$5:$A$639,$A14,$C$5:$C$639,$C14-1,$D$5:$D$639,$D14))-1))) | R14: =IF(OR($A14="",J14="",$C14=""),"",IF(COUNTIFS($A$5:$A$639,$A14,$C$5:$C$639,$C14-1,$D$5:$D$639,$D14,J$5:J$639,"<>")=0,"",IF(OR(SUMIFS(J$5:J$639,$A$5:$A$639,$A14,$C$5:$C$639,$C14-1,$D$5:$D$639,$D14)=0,J14*SUMIFS(J$5:J$639,$A$5:$A$639,$A14,$C$5:$C$639,$C14-1,$D$5:$D$639,$D14)<0),"n.s.",ABS(J14)/ABS(SUMIFS(J$5:J$639,$A$5:$A$639,$A14,$C$5:$C$639,$C14-1,$D$5:$D$639,$D14))-1))) | S14: =IF(OR($A14="",K14="",$C14=""),"",IF(COUNTIFS($A$5:$A$639,$A14,$C$5:$C$639,$C14-1,$D$5:$D$639,$D14,K$5:K$639,"<>")=0,"",IF(OR(SUMIFS(K$5:K$639,$A$5:$A$639,$A14,$C$5:$C$639,$C14-1,$D$5:$D$639,$D14)=0,K14*SUMIFS(K$5:K$639,$A$5:$A$639,$A14,$C$5:$C$639,$C14-1,$D$5:$D$639,$D14)<0),"n.s.",ABS(K14)/ABS(SUMIFS(K$5:K$639,$A$5:$A$639,$A14,$C$5:$C$639,$C14-1,$D$5:$D$639,$D14))-1))) | T14: =IF(OR($A14="",L14="",$C14=""),"",IF(COUNTIFS($A$5:$A$639,$A14,$C$5:$C$639,$C14-1,$D$5:$D$639,$D14,L$5:L$639,"<>")=0,"",IF(OR(SUMIFS(L$5:L$639,$A$5:$A$639,$A14,$C$5:$C$639,$C14-1,$D$5:$D$639,$D14)=0,L14*SUMIFS(L$5:L$639,$A$5:$A$639,$A14,$C$5:$C$639,$C14-1,$D$5:$D$639,$D14)<0),"n.s.",ABS(L14)/ABS(SUMIFS(L$5:L$639,$A$5:$A$639,$A14,$C$5:$C$639,$C14-1,$D$5:$D$639,$D14))-1))) | U14: =IF(OR($A14="",M14="",$C14=""),"",IF(COUNTIFS($A$5:$A$639,$A14,$C$5:$C$639,$C14-1,$D$5:$D$639,$D14,M$5:M$639,"<>")=0,"",IF(OR(SUMIFS(M$5:M$639,$A$5:$A$639,$A14,$C$5:$C$639,$C14-1,$D$5:$D$639,$D14)=0,M14*SUMIFS(M$5:M$639,$A$5:$A$639,$A14,$C$5:$C$639,$C14-1,$D$5:$D$639,$D14)<0),"n.s.",ABS(M14)/ABS(SUMIFS(M$5:M$639,$A$5:$A$639,$A14,$C$5:$C$639,$C14-1,$D$5:$D$639,$D14))-1)))
A15: NTLC | B15: =IF(A15="","",IFERROR(VLOOKUP(A15,Titres!$A$2:$B$400,2,FALSE),"Ticker inconnu")) | C15: 2024 | D15: S1 | N15: =IF(A15="","",COUNT(H15:M15)/6) | O15: =IF(COUNT(H15:M15)=0,"",IF(LEN(IF(COUNT(I15,J15)=2,IF(J15>I15+1,"EBE > VA ",""),"")&IF(COUNT(H15,M15)=2,IF(ABS(M15)>ABS(H15),"RN > CA ",""),"")&IF(COUNT(H15,K15)=2,IF(ABS(K15)>ABS(H15),"RE > CA ",""),""))=0,"OK",IF(COUNT(I15,J15)=2,IF(J15>I15+1,"EBE > VA ",""),"")&IF(COUNT(H15,M15)=2,IF(ABS(M15)>ABS(H15),"RN > CA ",""),"")&IF(COUNT(H15,K15)=2,IF(ABS(K15)>ABS(H15),"RE > CA ",""),""))) | P15: =IF(OR($A15="",H15="",$C15=""),"",IF(COUNTIFS($A$5:$A$639,$A15,$C$5:$C$639,$C15-1,$D$5:$D$639,$D15,H$5:H$639,"<>")=0,"",IF(OR(SUMIFS(H$5:H$639,$A$5:$A$639,$A15,$C$5:$C$639,$C15-1,$D$5:$D$639,$D15)=0,H15*SUMIFS(H$5:H$639,$A$5:$A$639,$A15,$C$5:$C$639,$C15-1,$D$5:$D$639,$D15)<0),"n.s.",ABS(H15)/ABS(SUMIFS(H$5:H$639,$A$5:$A$639,$A15,$C$5:$C$639,$C15-1,$D$5:$D$639,$D15))-1))) | Q15: =IF(OR($A15="",I15="",$C15=""),"",IF(COUNTIFS($A$5:$A$639,$A15,$C$5:$C$639,$C15-1,$D$5:$D$639,$D15,I$5:I$639,"<>")=0,"",IF(OR(SUMIFS(I$5:I$639,$A$5:$A$639,$A15,$C$5:$C$639,$C15-1,$D$5:$D$639,$D15)=0,I15*SUMIFS(I$5:I$639,$A$5:$A$639,$A15,$C$5:$C$639,$C15-1,$D$5:$D$639,$D15)<0),"n.s.",ABS(I15)/ABS(SUMIFS(I$5:I$639,$A$5:$A$639,$A15,$C$5:$C$639,$C15-1,$D$5:$D$639,$D15))-1))) | R15: =IF(OR($A15="",J15="",$C15=""),"",IF(COUNTIFS($A$5:$A$639,$A15,$C$5:$C$639,$C15-1,$D$5:$D$639,$D15,J$5:J$639,"<>")=0,"",IF(OR(SUMIFS(J$5:J$639,$A$5:$A$639,$A15,$C$5:$C$639,$C15-1,$D$5:$D$639,$D15)=0,J15*SUMIFS(J$5:J$639,$A$5:$A$639,$A15,$C$5:$C$639,$C15-1,$D$5:$D$639,$D15)<0),"n.s.",ABS(J15)/ABS(SUMIFS(J$5:J$639,$A$5:$A$639,$A15,$C$5:$C$639,$C15-1,$D$5:$D$639,$D15))-1))) | S15: =IF(OR($A15="",K15="",$C15=""),"",IF(COUNTIFS($A$5:$A$639,$A15,$C$5:$C$639,$C15-1,$D$5:$D$639,$D15,K$5:K$639,"<>")=0,"",IF(OR(SUMIFS(K$5:K$639,$A$5:$A$639,$A15,$C$5:$C$639,$C15-1,$D$5:$D$639,$D15)=0,K15*SUMIFS(K$5:K$639,$A$5:$A$639,$A15,$C$5:$C$639,$C15-1,$D$5:$D$639,$D15)<0),"n.s.",ABS(K15)/ABS(SUMIFS(K$5:K$639,$A$5:$A$639,$A15,$C$5:$C$639,$C15-1,$D$5:$D$639,$D15))-1))) | T15: =IF(OR($A15="",L15="",$C15=""),"",IF(COUNTIFS($A$5:$A$639,$A15,$C$5:$C$639,$C15-1,$D$5:$D$639,$D15,L$5:L$639,"<>")=0,"",IF(OR(SUMIFS(L$5:L$639,$A$5:$A$639,$A15,$C$5:$C$639,$C15-1,$D$5:$D$639,$D15)=0,L15*SUMIFS(L$5:L$639,$A$5:$A$639,$A15,$C$5:$C$639,$C15-1,$D$5:$D$639,$D15)<0),"n.s.",ABS(L15)/ABS(SUMIFS(L$5:L$639,$A$5:$A$639,$A15,$C$5:$C$639,$C15-1,$D$5:$D$639,$D15))-1))) | U15: =IF(OR($A15="",M15="",$C15=""),"",IF(COUNTIFS($A$5:$A$639,$A15,$C$5:$C$639,$C15-1,$D$5:$D$639,$D15,M$5:M$639,"<>")=0,"",IF(OR(SUMIFS(M$5:M$639,$A$5:$A$639,$A15,$C$5:$C$639,$C15-1,$D$5:$D$639,$D15)=0,M15*SUMIFS(M$5:M$639,$A$5:$A$639,$A15,$C$5:$C$639,$C15-1,$D$5:$D$639,$D15)<0),"n.s.",ABS(M15)/ABS(SUMIFS(M$5:M$639,$A$5:$A$639,$A15,$C$5:$C$639,$C15-1,$D$5:$D$639,$D15))-1)))
A16: NTLC | B16: =IF(A16="","",IFERROR(VLOOKUP(A16,Titres!$A$2:$B$400,2,FALSE),"Ticker inconnu")) | C16: 2024 | D16: T3 | N16: =IF(A16="","",COUNT(H16:M16)/6) | O16: =IF(COUNT(H16:M16)=0,"",IF(LEN(IF(COUNT(I16,J16)=2,IF(J16>I16+1,"EBE > VA ",""),"")&IF(COUNT(H16,M16)=2,IF(ABS(M16)>ABS(H16),"RN > CA ",""),"")&IF(COUNT(H16,K16)=2,IF(ABS(K16)>ABS(H16),"RE > CA ",""),""))=0,"OK",IF(COUNT(I16,J16)=2,IF(J16>I16+1,"EBE > VA ",""),"")&IF(COUNT(H16,M16)=2,IF(ABS(M16)>ABS(H16),"RN > CA ",""),"")&IF(COUNT(H16,K16)=2,IF(ABS(K16)>ABS(H16),"RE > CA ",""),""))) | P16: =IF(OR($A16="",H16="",$C16=""),"",IF(COUNTIFS($A$5:$A$639,$A16,$C$5:$C$639,$C16-1,$D$5:$D$639,$D16,H$5:H$639,"<>")=0,"",IF(OR(SUMIFS(H$5:H$639,$A$5:$A$639,$A16,$C$5:$C$639,$C16-1,$D$5:$D$639,$D16)=0,H16*SUMIFS(H$5:H$639,$A$5:$A$639,$A16,$C$5:$C$639,$C16-1,$D$5:$D$639,$D16)<0),"n.s.",ABS(H16)/ABS(SUMIFS(H$5:H$639,$A$5:$A$639,$A16,$C$5:$C$639,$C16-1,$D$5:$D$639,$D16))-1))) | Q16: =IF(OR($A16="",I16="",$C16=""),"",IF(COUNTIFS($A$5:$A$639,$A16,$C$5:$C$639,$C16-1,$D$5:$D$639,$D16,I$5:I$639,"<>")=0,"",IF(OR(SUMIFS(I$5:I$639,$A$5:$A$639,$A16,$C$5:$C$639,$C16-1,$D$5:$D$639,$D16)=0,I16*SUMIFS(I$5:I$639,$A$5:$A$639,$A16,$C$5:$C$639,$C16-1,$D$5:$D$639,$D16)<0),"n.s.",ABS(I16)/ABS(SUMIFS(I$5:I$639,$A$5:$A$639,$A16,$C$5:$C$639,$C16-1,$D$5:$D$639,$D16))-1))) | R16: =IF(OR($A16="",J16="",$C16=""),"",IF(COUNTIFS($A$5:$A$639,$A16,$C$5:$C$639,$C16-1,$D$5:$D$639,$D16,J$5:J$639,"<>")=0,"",IF(OR(SUMIFS(J$5:J$639,$A$5:$A$639,$A16,$C$5:$C$639,$C16-1,$D$5:$D$639,$D16)=0,J16*SUMIFS(J$5:J$639,$A$5:$A$639,$A16,$C$5:$C$639,$C16-1,$D$5:$D$639,$D16)<0),"n.s.",ABS(J16)/ABS(SUMIFS(J$5:J$639,$A$5:$A$639,$A16,$C$5:$C$639,$C16-1,$D$5:$D$639,$D16))-1))) | S16: =IF(OR($A16="",K16="",$C16=""),"",IF(COUNTIFS($A$5:$A$639,$A16,$C$5:$C$639,$C16-1,$D$5:$D$639,$D16,K$5:K$639,"<>")=0,"",IF(OR(SUMIFS(K$5:K$639,$A$5:$A$639,$A16,$C$5:$C$639,$C16-1,$D$5:$D$639,$D16)=0,K16*SUMIFS(K$5:K$639,$A$5:$A$639,$A16,$C$5:$C$639,$C16-1,$D$5:$D$639,$D16)<0),"n.s.",ABS(K16)/ABS(SUMIFS(K$5:K$639,$A$5:$A$639,$A16,$C$5:$C$639,$C16-1,$D$5:$D$639,$D16))-1))) | T16: =IF(OR($A16="",L16="",$C16=""),"",IF(COUNTIFS($A$5:$A$639,$A16,$C$5:$C$639,$C16-1,$D$5:$D$639,$D16,L$5:L$639,"<>")=0,"",IF(OR(SUMIFS(L$5:L$639,$A$5:$A$639,$A16,$C$5:$C$639,$C16-1,$D$5:$D$639,$D16)=0,L16*SUMIFS(L$5:L$639,$A$5:$A$639,$A16,$C$5:$C$639,$C16-1,$D$5:$D$639,$D16)<0),"n.s.",ABS(L16)/ABS(SUMIFS(L$5:L$639,$A$5:$A$639,$A16,$C$5:$C$639,$C16-1,$D$5:$D$639,$D16))-1))) | U16: =IF(OR($A16="",M16="",$C16=""),"",IF(COUNTIFS($A$5:$A$639,$A16,$C$5:$C$639,$C16-1,$D$5:$D$639,$D16,M$5:M$639,"<>")=0,"",IF(OR(SUMIFS(M$5:M$639,$A$5:$A$639,$A16,$C$5:$C$639,$C16-1,$D$5:$D$639,$D16)=0,M16*SUMIFS(M$5:M$639,$A$5:$A$639,$A16,$C$5:$C$639,$C16-1,$D$5:$D$639,$D16)<0),"n.s.",ABS(M16)/ABS(SUMIFS(M$5:M$639,$A$5:$A$639,$A16,$C$5:$C$639,$C16-1,$D$5:$D$639,$D16))-1)))
A17: NTLC | B17: =IF(A17="","",IFERROR(VLOOKUP(A17,Titres!$A$2:$B$400,2,FALSE),"Ticker inconnu")) | C17: 2025 | D17: T1 | E17: Publié | F17: 46142 | G17: https://www.richbourse.com/common/actualite/afficher-fichier/30-04-2026-nestle-ci-rapport-dactivites-1er-trimestre-2026 (comparatif N-1) | H17: 54079.13 | L17: 9487.853 | M17: 5479.04 | N17: =IF(A17="","",COUNT(H17:M17)/6) | O17: =IF(COUNT(H17:M17)=0,"",IF(LEN(IF(COUNT(I17,J17)=2,IF(J17>I17+1,"EBE > VA ",""),"")&IF(COUNT(H17,M17)=2,IF(ABS(M17)>ABS(H17),"RN > CA ",""),"")&IF(COUNT(H17,K17)=2,IF(ABS(K17)>ABS(H17),"RE > CA ",""),""))=0,"OK",IF(COUNT(I17,J17)=2,IF(J17>I17+1,"EBE > VA ",""),"")&IF(COUNT(H17,M17)=2,IF(ABS(M17)>ABS(H17),"RN > CA ",""),"")&IF(COUNT(H17,K17)=2,IF(ABS(K17)>ABS(H17),"RE > CA ",""),""))) | P17: =IF(OR($A17="",H17="",$C17=""),"",IF(COUNTIFS($A$5:$A$639,$A17,$C$5:$C$639,$C17-1,$D$5:$D$639,$D17,H$5:H$639,"<>")=0,"",IF(OR(SUMIFS(H$5:H$639,$A$5:$A$639,$A17,$C$5:$C$639,$C17-1,$D$5:$D$639,$D17)=0,H17*SUMIFS(H$5:H$639,$A$5:$A$639,$A17,$C$5:$C$639,$C17-1,$D$5:$D$639,$D17)<0),"n.s.",ABS(H17)/ABS(SUMIFS(H$5:H$639,$A$5:$A$639,$A17,$C$5:$C$639,$C17-1,$D$5:$D$639,$D17))-1))) | Q17: =IF(OR($A17="",I17="",$C17=""),"",IF(COUNTIFS($A$5:$A$639,$A17,$C$5:$C$639,$C17-1,$D$5:$D$639,$D17,I$5:I$639,"<>")=0,"",IF(OR(SUMIFS(I$5:I$639,$A$5:$A$639,$A17,$C$5:$C$639,$C17-1,$D$5:$D$639,$D17)=0,I17*SUMIFS(I$5:I$639,$A$5:$A$639,$A17,$C$5:$C$639,$C17-1,$D$5:$D$639,$D17)<0),"n.s.",ABS(I17)/ABS(SUMIFS(I$5:I$639,$A$5:$A$639,$A17,$C$5:$C$639,$C17-1,$D$5:$D$639,$D17))-1))) | R17: =IF(OR($A17="",J17="",$C17=""),"",IF(COUNTIFS($A$5:$A$639,$A17,$C$5:$C$639,$C17-1,$D$5:$D$639,$D17,J$5:J$639,"<>")=0,"",IF(OR(SUMIFS(J$5:J$639,$A$5:$A$639,$A17,$C$5:$C$639,$C17-1,$D$5:$D$639,$D17)=0,J17*SUMIFS(J$5:J$639,$A$5:$A$639,$A17,$C$5:$C$639,$C17-1,$D$5:$D$639,$D17)<0),"n.s.",ABS(J17)/ABS(SUMIFS(J$5:J$639,$A$5:$A$639,$A17,$C$5:$C$639,$C17-1,$D$5:$D$639,$D17))-1))) | S17: =IF(OR($A17="",K17="",$C17=""),"",IF(COUNTIFS($A$5:$A$639,$A17,$C$5:$C$639,$C17-1,$D$5:$D$639,$D17,K$5:K$639,"<>")=0,"",IF(OR(SUMIFS(K$5:K$639,$A$5:$A$639,$A17,$C$5:$C$639,$C17-1,$D$5:$D$639,$D17)=0,K17*SUMIFS(K$5:K$639,$A$5:$A$639,$A17,$C$5:$C$639,$C17-1,$D$5:$D$639,$D17)<0),"n.s.",ABS(K17)/ABS(SUMIFS(K$5:K$639,$A$5:$A$639,$A17,$C$5:$C$639,$C17-1,$D$5:$D$639,$D17))-1))) | T17: =IF(OR($A17="",L17="",$C17=""),"",IF(COUNTIFS($A$5:$A$639,$A17,$C$5:$C$639,$C17-1,$D$5:$D$639,$D17,L$5:L$639,"<>")=0,"",IF(OR(SUMIFS(L$5:L$639,$A$5:$A$639,$A17,$C$5:$C$639,$C17-1,$D$5:$D$639,$D17)=0,L17*SUMIFS(L$5:L$639,$A$5:$A$639,$A17,$C$5:$C$639,$C17-1,$D$5:$D$639,$D17)<0),"n.s.",ABS(L17)/ABS(SUMIFS(L$5:L$639,$A$5:$A$639,$A17,$C$5:$C$639,$C17-1,$D$5:$D$639,$D17))-1))) | U17: =IF(OR($A17="",M17="",$C17=""),"",IF(COUNTIFS($A$5:$A$639,$A17,$C$5:$C$639,$C17-1,$D$5:$D$639,$D17,M$5:M$639,"<>")=0,"",IF(OR(SUMIFS(M$5:M$639,$A$5:$A$639,$A17,$C$5:$C$639,$C17-1,$D$5:$D$639,$D17)=0,M17*SUMIFS(M$5:M$639,$A$5:$A$639,$A17,$C$5:$C$639,$C17-1,$D$5:$D$639,$D17)<0),"n.s.",ABS(M17)/ABS(SUMIFS(M$5:M$639,$A$5:$A$639,$A17,$C$5:$C$639,$C17-1,$D$5:$D$639,$D17))-1)))
A18: NTLC | B18: =IF(A18="","",IFERROR(VLOOKUP(A18,Titres!$A$2:$B$400,2,FALSE),"Ticker inconnu")) | C18: 2025 | D18: S1 | N18: =IF(A18="","",COUNT(H18:M18)/6) | O18: =IF(COUNT(H18:M18)=0,"",IF(LEN(IF(COUNT(I18,J18)=2,IF(J18>I18+1,"EBE > VA ",""),"")&IF(COUNT(H18,M18)=2,IF(ABS(M18)>ABS(H18),"RN > CA ",""),"")&IF(COUNT(H18,K18)=2,IF(ABS(K18)>ABS(H18),"RE > CA ",""),""))=0,"OK",IF(COUNT(I18,J18)=2,IF(J18>I18+1,"EBE > VA ",""),"")&IF(COUNT(H18,M18)=2,IF(ABS(M18)>ABS(H18),"RN > CA ",""),"")&IF(COUNT(H18,K18)=2,IF(ABS(K18)>ABS(H18),"RE > CA ",""),""))) | P18: =IF(OR($A18="",H18="",$C18=""),"",IF(COUNTIFS($A$5:$A$639,$A18,$C$5:$C$639,$C18-1,$D$5:$D$639,$D18,H$5:H$639,"<>")=0,"",IF(OR(SUMIFS(H$5:H$639,$A$5:$A$639,$A18,$C$5:$C$639,$C18-1,$D$5:$D$639,$D18)=0,H18*SUMIFS(H$5:H$639,$A$5:$A$639,$A18,$C$5:$C$639,$C18-1,$D$5:$D$639,$D18)<0),"n.s.",ABS(H18)/ABS(SUMIFS(H$5:H$639,$A$5:$A$639,$A18,$C$5:$C$639,$C18-1,$D$5:$D$639,$D18))-1))) | Q18: =IF(OR($A18="",I18="",$C18=""),"",IF(COUNTIFS($A$5:$A$639,$A18,$C$5:$C$639,$C18-1,$D$5:$D$639,$D18,I$5:I$639,"<>")=0,"",IF(OR(SUMIFS(I$5:I$639,$A$5:$A$639,$A18,$C$5:$C$639,$C18-1,$D$5:$D$639,$D18)=0,I18*SUMIFS(I$5:I$639,$A$5:$A$639,$A18,$C$5:$C$639,$C18-1,$D$5:$D$639,$D18)<0),"n.s.",ABS(I18)/ABS(SUMIFS(I$5:I$639,$A$5:$A$639,$A18,$C$5:$C$639,$C18-1,$D$5:$D$639,$D18))-1))) | R18: =IF(OR($A18="",J18="",$C18=""),"",IF(COUNTIFS($A$5:$A$639,$A18,$C$5:$C$639,$C18-1,$D$5:$D$639,$D18,J$5:J$639,"<>")=0,"",IF(OR(SUMIFS(J$5:J$639,$A$5:$A$639,$A18,$C$5:$C$639,$C18-1,$D$5:$D$639,$D18)=0,J18*SUMIFS(J$5:J$639,$A$5:$A$639,$A18,$C$5:$C$639,$C18-1,$D$5:$D$639,$D18)<0),"n.s.",ABS(J18)/ABS(SUMIFS(J$5:J$639,$A$5:$A$639,$A18,$C$5:$C$639,$C18-1,$D$5:$D$639,$D18))-1))) | S18: =IF(OR($A18="",K18="",$C18=""),"",IF(COUNTIFS($A$5:$A$639,$A18,$C$5:$C$639,$C18-1,$D$5:$D$639,$D18,K$5:K$639,"<>")=0,"",IF(OR(SUMIFS(K$5:K$639,$A$5:$A$639,$A18,$C$5:$C$639,$C18-1,$D$5:$D$639,$D18)=0,K18*SUMIFS(K$5:K$639,$A$5:$A$639,$A18,$C$5:$C$639,$C18-1,$D$5:$D$639,$D18)<0),"n.s.",ABS(K18)/ABS(SUMIFS(K$5:K$639,$A$5:$A$639,$A18,$C$5:$C$639,$C18-1,$D$5:$D$639,$D18))-1))) | T18: =IF(OR($A18="",L18="",$C18=""),"",IF(COUNTIFS($A$5:$A$639,$A18,$C$5:$C$639,$C18-1,$D$5:$D$639,$D18,L$5:L$639,"<>")=0,"",IF(OR(SUMIFS(L$5:L$639,$A$5:$A$639,$A18,$C$5:$C$639,$C18-1,$D$5:$D$639,$D18)=0,L18*SUMIFS(L$5:L$639,$A$5:$A$639,$A18,$C$5:$C$639,$C18-1,$D$5:$D$639,$D18)<0),"n.s.",ABS(L18)/ABS(SUMIFS(L$5:L$639,$A$5:$A$639,$A18,$C$5:$C$639,$C18-1,$D$5:$D$639,$D18))-1))) | U18: =IF(OR($A18="",M18="",$C18=""),"",IF(COUNTIFS($A$5:$A$639,$A18,$C$5:$C$639,$C18-1,$D$5:$D$639,$D18,M$5:M$639,"<>")=0,"",IF(OR(SUMIFS(M$5:M$639,$A$5:$A$639,$A18,$C$5:$C$639,$C18-1,$D$5:$D$639,$D18)=0,M18*SUMIFS(M$5:M$639,$A$5:$A$639,$A18,$C$5:$C$639,$C18-1,$D$5:$D$639,$D18)<0),"n.s.",ABS(M18)/ABS(SUMIFS(M$5:M$639,$A$5:$A$639,$A18,$C$5:$C$639,$C18-1,$D$5:$D$639,$D18))-1)))
A19: NTLC | B19: =IF(A19="","",IFERROR(VLOOKUP(A19,Titres!$A$2:$B$400,2,FALSE),"Ticker inconnu")) | C19: 2025 | D19: T3 | N19: =IF(A19="","",COUNT(H19:M19)/6) | O19: =IF(COUNT(H19:M19)=0,"",IF(LEN(IF(COUNT(I19,J19)=2,IF(J19>I19+1,"EBE > VA ",""),"")&IF(COUNT(H19,M19)=2,IF(ABS(M19)>ABS(H19),"RN > CA ",""),"")&IF(COUNT(H19,K19)=2,IF(ABS(K19)>ABS(H19),"RE > CA ",""),""))=0,"OK",IF(COUNT(I19,J19)=2,IF(J19>I19+1,"EBE > VA ",""),"")&IF(COUNT(H19,M19)=2,IF(ABS(M19)>ABS(H19),"RN > CA ",""),"")&IF(COUNT(H19,K19)=2,IF(ABS(K19)>ABS(H19),"RE > CA ",""),""))) | P19: =IF(OR($A19="",H19="",$C19=""),"",IF(COUNTIFS($A$5:$A$639,$A19,$C$5:$C$639,$C19-1,$D$5:$D$639,$D19,H$5:H$639,"<>")=0,"",IF(OR(SUMIFS(H$5:H$639,$A$5:$A$639,$A19,$C$5:$C$639,$C19-1,$D$5:$D$639,$D19)=0,H19*SUMIFS(H$5:H$639,$A$5:$A$639,$A19,$C$5:$C$639,$C19-1,$D$5:$D$639,$D19)<0),"n.s.",ABS(H19)/ABS(SUMIFS(H$5:H$639,$A$5:$A$639,$A19,$C$5:$C$639,$C19-1,$D$5:$D$639,$D19))-1))) | Q19: =IF(OR($A19="",I19="",$C19=""),"",IF(COUNTIFS($A$5:$A$639,$A19,$C$5:$C$639,$C19-1,$D$5:$D$639,$D19,I$5:I$639,"<>")=0,"",IF(OR(SUMIFS(I$5:I$639,$A$5:$A$639,$A19,$C$5:$C$639,$C19-1,$D$5:$D$639,$D19)=0,I19*SUMIFS(I$5:I$639,$A$5:$A$639,$A19,$C$5:$C$639,$C19-1,$D$5:$D$639,$D19)<0),"n.s.",ABS(I19)/ABS(SUMIFS(I$5:I$639,$A$5:$A$639,$A19,$C$5:$C$639,$C19-1,$D$5:$D$639,$D19))-1))) | R19: =IF(OR($A19="",J19="",$C19=""),"",IF(COUNTIFS($A$5:$A$639,$A19,$C$5:$C$639,$C19-1,$D$5:$D$639,$D19,J$5:J$639,"<>")=0,"",IF(OR(SUMIFS(J$5:J$639,$A$5:$A$639,$A19,$C$5:$C$639,$C19-1,$D$5:$D$639,$D19)=0,J19*SUMIFS(J$5:J$639,$A$5:$A$639,$A19,$C$5:$C$639,$C19-1,$D$5:$D$639,$D19)<0),"n.s.",ABS(J19)/ABS(SUMIFS(J$5:J$639,$A$5:$A$639,$A19,$C$5:$C$639,$C19-1,$D$5:$D$639,$D19))-1))) | S19: =IF(OR($A19="",K19="",$C19=""),"",IF(COUNTIFS($A$5:$A$639,$A19,$C$5:$C$639,$C19-1,$D$5:$D$639,$D19,K$5:K$639,"<>")=0,"",IF(OR(SUMIFS(K$5:K$639,$A$5:$A$639,$A19,$C$5:$C$639,$C19-1,$D$5:$D$639,$D19)=0,K19*SUMIFS(K$5:K$639,$A$5:$A$639,$A19,$C$5:$C$639,$C19-1,$D$5:$D$639,$D19)<0),"n.s.",ABS(K19)/ABS(SUMIFS(K$5:K$639,$A$5:$A$639,$A19,$C$5:$C$639,$C19-1,$D$5:$D$639,$D19))-1))) | T19: =IF(OR($A19="",L19="",$C19=""),"",IF(COUNTIFS($A$5:$A$639,$A19,$C$5:$C$639,$C19-1,$D$5:$D$639,$D19,L$5:L$639,"<>")=0,"",IF(OR(SUMIFS(L$5:L$639,$A$5:$A$639,$A19,$C$5:$C$639,$C19-1,$D$5:$D$639,$D19)=0,L19*SUMIFS(L$5:L$639,$A$5:$A$639,$A19,$C$5:$C$639,$C19-1,$D$5:$D$639,$D19)<0),"n.s.",ABS(L19)/ABS(SUMIFS(L$5:L$639,$A$5:$A$639,$A19,$C$5:$C$639,$C19-1,$D$5:$D$639,$D19))-1))) | U19: =IF(OR($A19="",M19="",$C19=""),"",IF(COUNTIFS($A$5:$A$639,$A19,$C$5:$C$639,$C19-1,$D$5:$D$639,$D19,M$5:M$639,"<>")=0,"",IF(OR(SUMIFS(M$5:M$639,$A$5:$A$639,$A19,$C$5:$C$639,$C19-1,$D$5:$D$639,$D19)=0,M19*SUMIFS(M$5:M$639,$A$5:$A$639,$A19,$C$5:$C$639,$C19-1,$D$5:$D$639,$D19)<0),"n.s.",ABS(M19)/ABS(SUMIFS(M$5:M$639,$A$5:$A$639,$A19,$C$5:$C$639,$C19-1,$D$5:$D$639,$D19))-1)))
A20: NTLC | B20: =IF(A20="","",IFERROR(VLOOKUP(A20,Titres!$A$2:$B$400,2,FALSE),"Ticker inconnu")) | C20: 2026 | D20: T1 | E20: Publié | F20: 46142 | G20: https://www.richbourse.com/common/actualite/afficher-fichier/30-04-2026-nestle-ci-rapport-dactivites-1er-trimestre-2026 | H20: 70821.658 | L20: 10874.637 | M20: 7525.623 | N20: =IF(A20="","",COUNT(H20:M20)/6) | O20: =IF(COUNT(H20:M20)=0,"",IF(LEN(IF(COUNT(I20,J20)=2,IF(J20>I20+1,"EBE > VA ",""),"")&IF(COUNT(H20,M20)=2,IF(ABS(M20)>ABS(H20),"RN > CA ",""),"")&IF(COUNT(H20,K20)=2,IF(ABS(K20)>ABS(H20),"RE > CA ",""),""))=0,"OK",IF(COUNT(I20,J20)=2,IF(J20>I20+1,"EBE > VA ",""),"")&IF(COUNT(H20,M20)=2,IF(ABS(M20)>ABS(H20),"RN > CA ",""),"")&IF(COUNT(H20,K20)=2,IF(ABS(K20)>ABS(H20),"RE > CA ",""),""))) | P20: =IF(OR($A20="",H20="",$C20=""),"",IF(COUNTIFS($A$5:$A$639,$A20,$C$5:$C$639,$C20-1,$D$5:$D$639,$D20,H$5:H$639,"<>")=0,"",IF(OR(SUMIFS(H$5:H$639,$A$5:$A$639,$A20,$C$5:$C$639,$C20-1,$D$5:$D$639,$D20)=0,H20*SUMIFS(H$5:H$639,$A$5:$A$639,$A20,$C$5:$C$639,$C20-1,$D$5:$D$639,$D20)<0),"n.s.",ABS(H20)/ABS(SUMIFS(H$5:H$639,$A$5:$A$639,$A20,$C$5:$C$639,$C20-1,$D$5:$D$639,$D20))-1))) | Q20: =IF(OR($A20="",I20="",$C20=""),"",IF(COUNTIFS($A$5:$A$639,$A20,$C$5:$C$639,$C20-1,$D$5:$D$639,$D20,I$5:I$639,"<>")=0,"",IF(OR(SUMIFS(I$5:I$639,$A$5:$A$639,$A20,$C$5:$C$639,$C20-1,$D$5:$D$639,$D20)=0,I20*SUMIFS(I$5:I$639,$A$5:$A$639,$A20,$C$5:$C$639,$C20-1,$D$5:$D$639,$D20)<0),"n.s.",ABS(I20)/ABS(SUMIFS(I$5:I$639,$A$5:$A$639,$A20,$C$5:$C$639,$C20-1,$D$5:$D$639,$D20))-1))) | R20: =IF(OR($A20="",J20="",$C20=""),"",IF(COUNTIFS($A$5:$A$639,$A20,$C$5:$C$639,$C20-1,$D$5:$D$639,$D20,J$5:J$639,"<>")=0,"",IF(OR(SUMIFS(J$5:J$639,$A$5:$A$639,$A20,$C$5:$C$639,$C20-1,$D$5:$D$639,$D20)=0,J20*SUMIFS(J$5:J$639,$A$5:$A$639,$A20,$C$5:$C$639,$C20-1,$D$5:$D$639,$D20)<0),"n.s.",ABS(J20)/ABS(SUMIFS(J$5:J$639,$A$5:$A$639,$A20,$C$5:$C$639,$C20-1,$D$5:$D$639,$D20))-1))) | S20: =IF(OR($A20="",K20="",$C20=""),"",IF(COUNTIFS($A$5:$A$639,$A20,$C$5:$C$639,$C20-1,$D$5:$D$639,$D20,K$5:K$639,"<>")=0,"",IF(OR(SUMIFS(K$5:K$639,$A$5:$A$639,$A20,$C$5:$C$639,$C20-1,$D$5:$D$639,$D20)=0,K20*SUMIFS(K$5:K$639,$A$5:$A$639,$A20,$C$5:$C$639,$C20-1,$D$5:$D$639,$D20)<0),"n.s.",ABS(K20)/ABS(SUMIFS(K$5:K$639,$A$5:$A$639,$A20,$C$5:$C$639,$C20-1,$D$5:$D$639,$D20))-1))) | T20: =IF(OR($A20="",L20="",$C20=""),"",IF(COUNTIFS($A$5:$A$639,$A20,$C$5:$C$639,$C20-1,$D$5:$D$639,$D20,L$5:L$639,"<>")=0,"",IF(OR(SUMIFS(L$5:L$639,$A$5:$A$639,$A20,$C$5:$C$639,$C20-1,$D$5:$D$639,$D20)=0,L20*SUMIFS(L$5:L$639,$A$5:$A$639,$A20,$C$5:$C$639,$C20-1,$D$5:$D$639,$D20)<0),"n.s.",ABS(L20)/ABS(SUMIFS(L$5:L$639,$A$5:$A$639,$A20,$C$5:$C$639,$C20-1,$D$5:$D$639,$D20))-1))) | U20: =IF(OR($A20="",M20="",$C20=""),"",IF(COUNTIFS($A$5:$A$639,$A20,$C$5:$C$639,$C20-1,$D$5:$D$639,$D20,M$5:M$639,"<>")=0,"",IF(OR(SUMIFS(M$5:M$639,$A$5:$A$639,$A20,$C$5:$C$639,$C20-1,$D$5:$D$639,$D20)=0,M20*SUMIFS(M$5:M$639,$A$5:$A$639,$A20,$C$5:$C$639,$C20-1,$D$5:$D$639,$D20)<0),"n.s.",ABS(M20)/ABS(SUMIFS(M$5:M$639,$A$5:$A$639,$A20,$C$5:$C$639,$C20-1,$D$5:$D$639,$D20))-1)))
A21: NTLC | B21: =IF(A21="","",IFERROR(VLOOKUP(A21,Titres!$A$2:$B$400,2,FALSE),"Ticker inconnu")) | C21: 2026 | D21: S1 | N21: =IF(A21="","",COUNT(H21:M21)/6) | O21: =IF(COUNT(H21:M21)=0,"",IF(LEN(IF(COUNT(I21,J21)=2,IF(J21>I21+1,"EBE > VA ",""),"")&IF(COUNT(H21,M21)=2,IF(ABS(M21)>ABS(H21),"RN > CA ",""),"")&IF(COUNT(H21,K21)=2,IF(ABS(K21)>ABS(H21),"RE > CA ",""),""))=0,"OK",IF(COUNT(I21,J21)=2,IF(J21>I21+1,"EBE > VA ",""),"")&IF(COUNT(H21,M21)=2,IF(ABS(M21)>ABS(H21),"RN > CA ",""),"")&IF(COUNT(H21,K21)=2,IF(ABS(K21)>ABS(H21),"RE > CA ",""),""))) | P21: =IF(OR($A21="",H21="",$C21=""),"",IF(COUNTIFS($A$5:$A$639,$A21,$C$5:$C$639,$C21-1,$D$5:$D$639,$D21,H$5:H$639,"<>")=0,"",IF(OR(SUMIFS(H$5:H$639,$A$5:$A$639,$A21,$C$5:$C$639,$C21-1,$D$5:$D$639,$D21)=0,H21*SUMIFS(H$5:H$639,$A$5:$A$639,$A21,$C$5:$C$639,$C21-1,$D$5:$D$639,$D21)<0),"n.s.",ABS(H21)/ABS(SUMIFS(H$5:H$639,$A$5:$A$639,$A21,$C$5:$C$639,$C21-1,$D$5:$D$639,$D21))-1))) | Q21: =IF(OR($A21="",I21="",$C21=""),"",IF(COUNTIFS($A$5:$A$639,$A21,$C$5:$C$639,$C21-1,$D$5:$D$639,$D21,I$5:I$639,"<>")=0,"",IF(OR(SUMIFS(I$5:I$639,$A$5:$A$639,$A21,$C$5:$C$639,$C21-1,$D$5:$D$639,$D21)=0,I21*SUMIFS(I$5:I$639,$A$5:$A$639,$A21,$C$5:$C$639,$C21-1,$D$5:$D$639,$D21)<0),"n.s.",ABS(I21)/ABS(SUMIFS(I$5:I$639,$A$5:$A$639,$A21,$C$5:$C$639,$C21-1,$D$5:$D$639,$D21))-1))) | R21: =IF(OR($A21="",J21="",$C21=""),"",IF(COUNTIFS($A$5:$A$639,$A21,$C$5:$C$639,$C21-1,$D$5:$D$639,$D21,J$5:J$639,"<>")=0,"",IF(OR(SUMIFS(J$5:J$639,$A$5:$A$639,$A21,$C$5:$C$639,$C21-1,$D$5:$D$639,$D21)=0,J21*SUMIFS(J$5:J$639,$A$5:$A$639,$A21,$C$5:$C$639,$C21-1,$D$5:$D$639,$D21)<0),"n.s.",ABS(J21)/ABS(SUMIFS(J$5:J$639,$A$5:$A$639,$A21,$C$5:$C$639,$C21-1,$D$5:$D$639,$D21))-1))) | S21: =IF(OR($A21="",K21="",$C21=""),"",IF(COUNTIFS($A$5:$A$639,$A21,$C$5:$C$639,$C21-1,$D$5:$D$639,$D21,K$5:K$639,"<>")=0,"",IF(OR(SUMIFS(K$5:K$639,$A$5:$A$639,$A21,$C$5:$C$639,$C21-1,$D$5:$D$639,$D21)=0,K21*SUMIFS(K$5:K$639,$A$5:$A$639,$A21,$C$5:$C$639,$C21-1,$D$5:$D$639,$D21)<0),"n.s.",ABS(K21)/ABS(SUMIFS(K$5:K$639,$A$5:$A$639,$A21,$C$5:$C$639,$C21-1,$D$5:$D$639,$D21))-1))) | T21: =IF(OR($A21="",L21="",$C21=""),"",IF(COUNTIFS($A$5:$A$639,$A21,$C$5:$C$639,$C21-1,$D$5:$D$639,$D21,L$5:L$639,"<>")=0,"",IF(OR(SUMIFS(L$5:L$639,$A$5:$A$639,$A21,$C$5:$C$639,$C21-1,$D$5:$D$639,$D21)=0,L21*SUMIFS(L$5:L$639,$A$5:$A$639,$A21,$C$5:$C$639,$C21-1,$D$5:$D$639,$D21)<0),"n.s.",ABS(L21)/ABS(SUMIFS(L$5:L$639,$A$5:$A$639,$A21,$C$5:$C$639,$C21-1,$D$5:$D$639,$D21))-1))) | U21: =IF(OR($A21="",M21="",$C21=""),"",IF(COUNTIFS($A$5:$A$639,$A21,$C$5:$C$639,$C21-1,$D$5:$D$639,$D21,M$5:M$639,"<>")=0,"",IF(OR(SUMIFS(M$5:M$639,$A$5:$A$639,$A21,$C$5:$C$639,$C21-1,$D$5:$D$639,$D21)=0,M21*SUMIFS(M$5:M$639,$A$5:$A$639,$A21,$C$5:$C$639,$C21-1,$D$5:$D$639,$D21)<0),"n.s.",ABS(M21)/ABS(SUMIFS(M$5:M$639,$A$5:$A$639,$A21,$C$5:$C$639,$C21-1,$D$5:$D$639,$D21))-1)))
A22: NTLC | B22: =IF(A22="","",IFERROR(VLOOKUP(A22,Titres!$A$2:$B$400,2,FALSE),"Ticker inconnu")) | C22: 2026 | D22: T3 | N22: =IF(A22="","",COUNT(H22:M22)/6) | O22: =IF(COUNT(H22:M22)=0,"",IF(LEN(IF(COUNT(I22,J22)=2,IF(J22>I22+1,"EBE > VA ",""),"")&IF(COUNT(H22,M22)=2,IF(ABS(M22)>ABS(H22),"RN > CA ",""),"")&IF(COUNT(H22,K22)=2,IF(ABS(K22)>ABS(H22),"RE > CA ",""),""))=0,"OK",IF(COUNT(I22,J22)=2,IF(J22>I22+1,"EBE > VA ",""),"")&IF(COUNT(H22,M22)=2,IF(ABS(M22)>ABS(H22),"RN > CA ",""),"")&IF(COUNT(H22,K22)=2,IF(ABS(K22)>ABS(H22),"RE > CA ",""),""))) | P22: =IF(OR($A22="",H22="",$C22=""),"",IF(COUNTIFS($A$5:$A$639,$A22,$C$5:$C$639,$C22-1,$D$5:$D$639,$D22,H$5:H$639,"<>")=0,"",IF(OR(SUMIFS(H$5:H$639,$A$5:$A$639,$A22,$C$5:$C$639,$C22-1,$D$5:$D$639,$D22)=0,H22*SUMIFS(H$5:H$639,$A$5:$A$639,$A22,$C$5:$C$639,$C22-1,$D$5:$D$639,$D22)<0),"n.s.",ABS(H22)/ABS(SUMIFS(H$5:H$639,$A$5:$A$639,$A22,$C$5:$C$639,$C22-1,$D$5:$D$639,$D22))-1))) | Q22: =IF(OR($A22="",I22="",$C22=""),"",IF(COUNTIFS($A$5:$A$639,$A22,$C$5:$C$639,$C22-1,$D$5:$D$639,$D22,I$5:I$639,"<>")=0,"",IF(OR(SUMIFS(I$5:I$639,$A$5:$A$639,$A22,$C$5:$C$639,$C22-1,$D$5:$D$639,$D22)=0,I22*SUMIFS(I$5:I$639,$A$5:$A$639,$A22,$C$5:$C$639,$C22-1,$D$5:$D$639,$D22)<0),"n.s.",ABS(I22)/ABS(SUMIFS(I$5:I$639,$A$5:$A$639,$A22,$C$5:$C$639,$C22-1,$D$5:$D$639,$D22))-1))) | R22: =IF(OR($A22="",J22="",$C22=""),"",IF(COUNTIFS($A$5:$A$639,$A22,$C$5:$C$639,$C22-1,$D$5:$D$639,$D22,J$5:J$639,"<>")=0,"",IF(OR(SUMIFS(J$5:J$639,$A$5:$A$639,$A22,$C$5:$C$639,$C22-1,$D$5:$D$639,$D22)=0,J22*SUMIFS(J$5:J$639,$A$5:$A$639,$A22,$C$5:$C$639,$C22-1,$D$5:$D$639,$D22)<0),"n.s.",ABS(J22)/ABS(SUMIFS(J$5:J$639,$A$5:$A$639,$A22,$C$5:$C$639,$C22-1,$D$5:$D$639,$D22))-1))) | S22: =IF(OR($A22="",K22="",$C22=""),"",IF(COUNTIFS($A$5:$A$639,$A22,$C$5:$C$639,$C22-1,$D$5:$D$639,$D22,K$5:K$639,"<>")=0,"",IF(OR(SUMIFS(K$5:K$639,$A$5:$A$639,$A22,$C$5:$C$639,$C22-1,$D$5:$D$639,$D22)=0,K22*SUMIFS(K$5:K$639,$A$5:$A$639,$A22,$C$5:$C$639,$C22-1,$D$5:$D$639,$D22)<0),"n.s.",ABS(K22)/ABS(SUMIFS(K$5:K$639,$A$5:$A$639,$A22,$C$5:$C$639,$C22-1,$D$5:$D$639,$D22))-1))) | T22: =IF(OR($A22="",L22="",$C22=""),"",IF(COUNTIFS($A$5:$A$639,$A22,$C$5:$C$639,$C22-1,$D$5:$D$639,$D22,L$5:L$639,"<>")=0,"",IF(OR(SUMIFS(L$5:L$639,$A$5:$A$639,$A22,$C$5:$C$639,$C22-1,$D$5:$D$639,$D22)=0,L22*SUMIFS(L$5:L$639,$A$5:$A$639,$A22,$C$5:$C$639,$C22-1,$D$5:$D$639,$D22)<0),"n.s.",ABS(L22)/ABS(SUMIFS(L$5:L$639,$A$5:$A$639,$A22,$C$5:$C$639,$C22-1,$D$5:$D$639,$D22))-1))) | U22: =IF(OR($A22="",M22="",$C22=""),"",IF(COUNTIFS($A$5:$A$639,$A22,$C$5:$C$639,$C22-1,$D$5:$D$639,$D22,M$5:M$639,"<>")=0,"",IF(OR(SUMIFS(M$5:M$639,$A$5:$A$639,$A22,$C$5:$C$639,$C22-1,$D$5:$D$639,$D22)=0,M22*SUMIFS(M$5:M$639,$A$5:$A$639,$A22,$C$5:$C$639,$C22-1,$D$5:$D$639,$D22)<0),"n.s.",ABS(M22)/ABS(SUMIFS(M$5:M$639,$A$5:$A$639,$A22,$C$5:$C$639,$C22-1,$D$5:$D$639,$D22))-1)))
A23: PALC | B23: =IF(A23="","",IFERROR(VLOOKUP(A23,Titres!$A$2:$B$400,2,FALSE),"Ticker inconnu")) | C23: 2021 | D23: T1 | N23: =IF(A23="","",COUNT(H23:M23)/6) | O23: =IF(COUNT(H23:M23)=0,"",IF(LEN(IF(COUNT(I23,J23)=2,IF(J23>I23+1,"EBE > VA ",""),"")&IF(COUNT(H23,M23)=2,IF(ABS(M23)>ABS(H23),"RN > CA ",""),"")&IF(COUNT(H23,K23)=2,IF(ABS(K23)>ABS(H23),"RE > CA ",""),""))=0,"OK",IF(COUNT(I23,J23)=2,IF(J23>I23+1,"EBE > VA ",""),"")&IF(COUNT(H23,M23)=2,IF(ABS(M23)>ABS(H23),"RN > CA ",""),"")&IF(COUNT(H23,K23)=2,IF(ABS(K23)>ABS(H23),"RE > CA ",""),""))) | P23: =IF(OR($A23="",H23="",$C23=""),"",IF(COUNTIFS($A$5:$A$639,$A23,$C$5:$C$639,$C23-1,$D$5:$D$639,$D23,H$5:H$639,"<>")=0,"",IF(OR(SUMIFS(H$5:H$639,$A$5:$A$639,$A23,$C$5:$C$639,$C23-1,$D$5:$D$639,$D23)=0,H23*SUMIFS(H$5:H$639,$A$5:$A$639,$A23,$C$5:$C$639,$C23-1,$D$5:$D$639,$D23)<0),"n.s.",ABS(H23)/ABS(SUMIFS(H$5:H$639,$A$5:$A$639,$A23,$C$5:$C$639,$C23-1,$D$5:$D$639,$D23))-1))) | Q23: =IF(OR($A23="",I23="",$C23=""),"",IF(COUNTIFS($A$5:$A$639,$A23,$C$5:$C$639,$C23-1,$D$5:$D$639,$D23,I$5:I$639,"<>")=0,"",IF(OR(SUMIFS(I$5:I$639,$A$5:$A$639,$A23,$C$5:$C$639,$C23-1,$D$5:$D$639,$D23)=0,I23*SUMIFS(I$5:I$639,$A$5:$A$639,$A23,$C$5:$C$639,$C23-1,$D$5:$D$639,$D23)<0),"n.s.",ABS(I23)/ABS(SUMIFS(I$5:I$639,$A$5:$A$639,$A23,$C$5:$C$639,$C23-1,$D$5:$D$639,$D23))-1))) | R23: =IF(OR($A23="",J23="",$C23=""),"",IF(COUNTIFS($A$5:$A$639,$A23,$C$5:$C$639,$C23-1,$D$5:$D$639,$D23,J$5:J$639,"<>")=0,"",IF(OR(SUMIFS(J$5:J$639,$A$5:$A$639,$A23,$C$5:$C$639,$C23-1,$D$5:$D$639,$D23)=0,J23*SUMIFS(J$5:J$639,$A$5:$A$639,$A23,$C$5:$C$639,$C23-1,$D$5:$D$639,$D23)<0),"n.s.",ABS(J23)/ABS(SUMIFS(J$5:J$639,$A$5:$A$639,$A23,$C$5:$C$639,$C23-1,$D$5:$D$639,$D23))-1))) | S23: =IF(OR($A23="",K23="",$C23=""),"",IF(COUNTIFS($A$5:$A$639,$A23,$C$5:$C$639,$C23-1,$D$5:$D$639,$D23,K$5:K$639,"<>")=0,"",IF(OR(SUMIFS(K$5:K$639,$A$5:$A$639,$A23,$C$5:$C$639,$C23-1,$D$5:$D$639,$D23)=0,K23*SUMIFS(K$5:K$639,$A$5:$A$639,$A23,$C$5:$C$639,$C23-1,$D$5:$D$639,$D23)<0),"n.s.",ABS(K23)/ABS(SUMIFS(K$5:K$639,$A$5:$A$639,$A23,$C$5:$C$639,$C23-1,$D$5:$D$639,$D23))-1))) | T23: =IF(OR($A23="",L23="",$C23=""),"",IF(COUNTIFS($A$5:$A$639,$A23,$C$5:$C$639,$C23-1,$D$5:$D$639,$D23,L$5:L$639,"<>")=0,"",IF(OR(SUMIFS(L$5:L$639,$A$5:$A$639,$A23,$C$5:$C$639,$C23-1,$D$5:$D$639,$D23)=0,L23*SUMIFS(L$5:L$639,$A$5:$A$639,$A23,$C$5:$C$639,$C23-1,$D$5:$D$639,$D23)<0),"n.s.",ABS(L23)/ABS(SUMIFS(L$5:L$639,$A$5:$A$639,$A23,$C$5:$C$639,$C23-1,$D$5:$D$639,$D23))-1))) | U23: =IF(OR($A23="",M23="",$C23=""),"",IF(COUNTIFS($A$5:$A$639,$A23,$C$5:$C$639,$C23-1,$D$5:$D$639,$D23,M$5:M$639,"<>")=0,"",IF(OR(SUMIFS(M$5:M$639,$A$5:$A$639,$A23,$C$5:$C$639,$C23-1,$D$5:$D$639,$D23)=0,M23*SUMIFS(M$5:M$639,$A$5:$A$639,$A23,$C$5:$C$639,$C23-1,$D$5:$D$639,$D23)<0),"n.s.",ABS(M23)/ABS(SUMIFS(M$5:M$639,$A$5:$A$639,$A23,$C$5:$C$639,$C23-1,$D$5:$D$639,$D23))-1)))
